[2024-07-25T14:28:18.041-0300] {local_task_job_runner.py:120} INFO - ::group::Pre task execution logs
[2024-07-25T14:28:18.047-0300] {taskinstance.py:2076} INFO - Dependencies all met for dep_context=non-requeueable deps ti=<TaskInstance: Mercado_5m.get_5m_info scheduled__2024-07-25T13:25:00+00:00 [queued]>
[2024-07-25T14:28:18.050-0300] {taskinstance.py:2076} INFO - Dependencies all met for dep_context=requeueable deps ti=<TaskInstance: Mercado_5m.get_5m_info scheduled__2024-07-25T13:25:00+00:00 [queued]>
[2024-07-25T14:28:18.050-0300] {taskinstance.py:2306} INFO - Starting attempt 1 of 1
[2024-07-25T14:28:18.063-0300] {taskinstance.py:2330} INFO - Executing <Task(PythonOperator): get_5m_info> on 2024-07-25 13:25:00+00:00
[2024-07-25T14:28:18.065-0300] {standard_task_runner.py:64} INFO - Started process 2591081 to run task
[2024-07-25T14:28:18.067-0300] {standard_task_runner.py:90} INFO - Running: ['airflow', 'tasks', 'run', 'Mercado_5m', 'get_5m_info', 'scheduled__2024-07-25T13:25:00+00:00', '--job-id', '2116', '--raw', '--subdir', 'DAGS_FOLDER/mercado_dag.py', '--cfg-path', '/tmp/tmpnhne0aou']
[2024-07-25T14:28:18.068-0300] {standard_task_runner.py:91} INFO - Job 2116: Subtask get_5m_info
[2024-07-25T14:28:18.093-0300] {task_command.py:426} INFO - Running <TaskInstance: Mercado_5m.get_5m_info scheduled__2024-07-25T13:25:00+00:00 [running]> on host Galaxybook.
[2024-07-25T14:28:18.139-0300] {taskinstance.py:2648} INFO - Exporting env vars: AIRFLOW_CTX_DAG_OWNER='airflow' AIRFLOW_CTX_DAG_ID='Mercado_5m' AIRFLOW_CTX_TASK_ID='get_5m_info' AIRFLOW_CTX_EXECUTION_DATE='2024-07-25T13:25:00+00:00' AIRFLOW_CTX_TRY_NUMBER='1' AIRFLOW_CTX_DAG_RUN_ID='scheduled__2024-07-25T13:25:00+00:00'
[2024-07-25T14:28:18.139-0300] {taskinstance.py:430} INFO - ::endgroup::
[2024-07-25T14:28:18.146-0300] {taskinstance.py:441} INFO - ::group::Post task execution logs
[2024-07-25T14:28:18.146-0300] {taskinstance.py:2905} ERROR - Task failed with exception
Traceback (most recent call last):
  File "/home/hugoviana/Documentos/data_pipeline_airflow/.venv/lib/python3.12/site-packages/airflow/models/taskinstance.py", line 465, in _execute_task
    result = _execute_callable(context=context, **execute_callable_kwargs)
             ^^^^^^^^^^^^^^^^^^^^^^^^^^^^^^^^^^^^^^^^^^^^^^^^^^^^^^^^^^^^^
  File "/home/hugoviana/Documentos/data_pipeline_airflow/.venv/lib/python3.12/site-packages/airflow/models/taskinstance.py", line 432, in _execute_callable
    return execute_callable(context=context, **execute_callable_kwargs)
           ^^^^^^^^^^^^^^^^^^^^^^^^^^^^^^^^^^^^^^^^^^^^^^^^^^^^^^^^^^^^
  File "/home/hugoviana/Documentos/data_pipeline_airflow/.venv/lib/python3.12/site-packages/airflow/models/baseoperator.py", line 401, in wrapper
    return func(self, *args, **kwargs)
           ^^^^^^^^^^^^^^^^^^^^^^^^^^^
  File "/home/hugoviana/Documentos/data_pipeline_airflow/.venv/lib/python3.12/site-packages/airflow/operators/python.py", line 232, in execute
    context_merge(context, self.op_kwargs, templates_dict=self.templates_dict)
  File "/home/hugoviana/Documentos/data_pipeline_airflow/.venv/lib/python3.12/site-packages/airflow/utils/context.py", line 266, in context_merge
    context.update(*args, **kwargs)
  File "<frozen _collections_abc>", line 987, in update
ValueError: too many values to unpack (expected 2)
[2024-07-25T14:28:18.149-0300] {taskinstance.py:1206} INFO - Marking task as FAILED. dag_id=Mercado_5m, task_id=get_5m_info, run_id=scheduled__2024-07-25T13:25:00+00:00, execution_date=20240725T132500, start_date=20240725T172818, end_date=20240725T172818
[2024-07-25T14:28:18.159-0300] {standard_task_runner.py:110} ERROR - Failed to execute job 2116 for task get_5m_info (too many values to unpack (expected 2); 2591081)
[2024-07-25T14:28:18.200-0300] {local_task_job_runner.py:243} INFO - Task exited with return code 1
[2024-07-25T14:28:18.209-0300] {taskinstance.py:3503} INFO - 0 downstream tasks scheduled from follow-on schedule check
[2024-07-25T14:28:18.210-0300] {local_task_job_runner.py:222} INFO - ::endgroup::
[2024-07-25T14:30:24.860-0300] {local_task_job_runner.py:120} INFO - ::group::Pre task execution logs
[2024-07-25T14:30:24.867-0300] {taskinstance.py:2076} INFO - Dependencies all met for dep_context=non-requeueable deps ti=<TaskInstance: Mercado_5m.get_5m_info scheduled__2024-07-25T13:25:00+00:00 [queued]>
[2024-07-25T14:30:24.871-0300] {taskinstance.py:2076} INFO - Dependencies all met for dep_context=requeueable deps ti=<TaskInstance: Mercado_5m.get_5m_info scheduled__2024-07-25T13:25:00+00:00 [queued]>
[2024-07-25T14:30:24.872-0300] {taskinstance.py:2306} INFO - Starting attempt 1 of 1
[2024-07-25T14:30:24.885-0300] {taskinstance.py:2330} INFO - Executing <Task(PythonOperator): get_5m_info> on 2024-07-25 13:25:00+00:00
[2024-07-25T14:30:24.887-0300] {standard_task_runner.py:64} INFO - Started process 2593258 to run task
[2024-07-25T14:30:24.889-0300] {standard_task_runner.py:90} INFO - Running: ['airflow', 'tasks', 'run', 'Mercado_5m', 'get_5m_info', 'scheduled__2024-07-25T13:25:00+00:00', '--job-id', '2099', '--raw', '--subdir', 'DAGS_FOLDER/mercado_dag.py', '--cfg-path', '/tmp/tmp10enk5em']
[2024-07-25T14:30:24.890-0300] {standard_task_runner.py:91} INFO - Job 2099: Subtask get_5m_info
[2024-07-25T14:30:24.921-0300] {task_command.py:426} INFO - Running <TaskInstance: Mercado_5m.get_5m_info scheduled__2024-07-25T13:25:00+00:00 [running]> on host Galaxybook.
[2024-07-25T14:30:24.970-0300] {taskinstance.py:2648} INFO - Exporting env vars: AIRFLOW_CTX_DAG_OWNER='airflow' AIRFLOW_CTX_DAG_ID='Mercado_5m' AIRFLOW_CTX_TASK_ID='get_5m_info' AIRFLOW_CTX_EXECUTION_DATE='2024-07-25T13:25:00+00:00' AIRFLOW_CTX_TRY_NUMBER='1' AIRFLOW_CTX_DAG_RUN_ID='scheduled__2024-07-25T13:25:00+00:00'
[2024-07-25T14:30:24.971-0300] {taskinstance.py:430} INFO - ::endgroup::
[2024-07-25T14:30:24.978-0300] {taskinstance.py:441} INFO - ::group::Post task execution logs
[2024-07-25T14:30:24.978-0300] {taskinstance.py:2905} ERROR - Task failed with exception
Traceback (most recent call last):
  File "/home/hugoviana/Documentos/data_pipeline_airflow/.venv/lib/python3.12/site-packages/airflow/models/taskinstance.py", line 465, in _execute_task
    result = _execute_callable(context=context, **execute_callable_kwargs)
             ^^^^^^^^^^^^^^^^^^^^^^^^^^^^^^^^^^^^^^^^^^^^^^^^^^^^^^^^^^^^^
  File "/home/hugoviana/Documentos/data_pipeline_airflow/.venv/lib/python3.12/site-packages/airflow/models/taskinstance.py", line 432, in _execute_callable
    return execute_callable(context=context, **execute_callable_kwargs)
           ^^^^^^^^^^^^^^^^^^^^^^^^^^^^^^^^^^^^^^^^^^^^^^^^^^^^^^^^^^^^
  File "/home/hugoviana/Documentos/data_pipeline_airflow/.venv/lib/python3.12/site-packages/airflow/models/baseoperator.py", line 401, in wrapper
    return func(self, *args, **kwargs)
           ^^^^^^^^^^^^^^^^^^^^^^^^^^^
  File "/home/hugoviana/Documentos/data_pipeline_airflow/.venv/lib/python3.12/site-packages/airflow/operators/python.py", line 232, in execute
    context_merge(context, self.op_kwargs, templates_dict=self.templates_dict)
  File "/home/hugoviana/Documentos/data_pipeline_airflow/.venv/lib/python3.12/site-packages/airflow/utils/context.py", line 266, in context_merge
    context.update(*args, **kwargs)
  File "<frozen _collections_abc>", line 987, in update
ValueError: too many values to unpack (expected 2)
[2024-07-25T14:30:24.985-0300] {taskinstance.py:1206} INFO - Marking task as FAILED. dag_id=Mercado_5m, task_id=get_5m_info, run_id=scheduled__2024-07-25T13:25:00+00:00, execution_date=20240725T132500, start_date=20240725T173024, end_date=20240725T173024
[2024-07-25T14:30:24.997-0300] {standard_task_runner.py:110} ERROR - Failed to execute job 2099 for task get_5m_info (too many values to unpack (expected 2); 2593258)
[2024-07-25T14:30:25.024-0300] {local_task_job_runner.py:243} INFO - Task exited with return code 1
[2024-07-25T14:30:25.030-0300] {taskinstance.py:3503} INFO - 0 downstream tasks scheduled from follow-on schedule check
[2024-07-25T14:30:25.031-0300] {local_task_job_runner.py:222} INFO - ::endgroup::
[2024-07-25T15:00:33.853-0300] {local_task_job_runner.py:120} INFO - ::group::Pre task execution logs
[2024-07-25T15:00:33.859-0300] {taskinstance.py:2076} INFO - Dependencies all met for dep_context=non-requeueable deps ti=<TaskInstance: Mercado_5m.get_5m_info scheduled__2024-07-25T13:25:00+00:00 [queued]>
[2024-07-25T15:00:33.862-0300] {taskinstance.py:2076} INFO - Dependencies all met for dep_context=requeueable deps ti=<TaskInstance: Mercado_5m.get_5m_info scheduled__2024-07-25T13:25:00+00:00 [queued]>
[2024-07-25T15:00:33.862-0300] {taskinstance.py:2306} INFO - Starting attempt 1 of 1
[2024-07-25T15:00:33.874-0300] {taskinstance.py:2330} INFO - Executing <Task(PythonOperator): get_5m_info> on 2024-07-25 13:25:00+00:00
[2024-07-25T15:00:33.877-0300] {standard_task_runner.py:64} INFO - Started process 2619986 to run task
[2024-07-25T15:00:33.878-0300] {standard_task_runner.py:90} INFO - Running: ['airflow', 'tasks', 'run', 'Mercado_5m', 'get_5m_info', 'scheduled__2024-07-25T13:25:00+00:00', '--job-id', '2473', '--raw', '--subdir', 'DAGS_FOLDER/mercado_dag.py', '--cfg-path', '/tmp/tmpmvtb5nq_']
[2024-07-25T15:00:33.879-0300] {standard_task_runner.py:91} INFO - Job 2473: Subtask get_5m_info
[2024-07-25T15:00:33.914-0300] {task_command.py:426} INFO - Running <TaskInstance: Mercado_5m.get_5m_info scheduled__2024-07-25T13:25:00+00:00 [running]> on host Galaxybook.
[2024-07-25T15:00:33.980-0300] {taskinstance.py:2648} INFO - Exporting env vars: AIRFLOW_CTX_DAG_OWNER='airflow' AIRFLOW_CTX_DAG_ID='Mercado_5m' AIRFLOW_CTX_TASK_ID='get_5m_info' AIRFLOW_CTX_EXECUTION_DATE='2024-07-25T13:25:00+00:00' AIRFLOW_CTX_TRY_NUMBER='1' AIRFLOW_CTX_DAG_RUN_ID='scheduled__2024-07-25T13:25:00+00:00'
[2024-07-25T15:00:33.981-0300] {taskinstance.py:430} INFO - ::endgroup::
[2024-07-25T15:00:34.069-0300] {base.py:84} INFO - Using connection ID 'mercado_default' for task execution.
[2024-07-25T15:00:34.070-0300] {mercado_hook.py:31} INFO - URL: https://api.mercadobitcoin.net/api/v4/candles?symbol=BTC-BRL&resolution=5m&to=1721925000&from=1721924700
[2024-07-25T15:00:34.347-0300] {python.py:237} INFO - Done. Returned value was: None
[2024-07-25T15:00:34.348-0300] {taskinstance.py:441} INFO - ::group::Post task execution logs
[2024-07-25T15:00:34.353-0300] {taskinstance.py:1206} INFO - Marking task as SUCCESS. dag_id=Mercado_5m, task_id=get_5m_info, run_id=scheduled__2024-07-25T13:25:00+00:00, execution_date=20240725T132500, start_date=20240725T180033, end_date=20240725T180034
[2024-07-25T15:00:34.378-0300] {local_task_job_runner.py:243} INFO - Task exited with return code 0
[2024-07-25T15:00:34.384-0300] {taskinstance.py:3503} INFO - 0 downstream tasks scheduled from follow-on schedule check
[2024-07-25T15:00:34.384-0300] {local_task_job_runner.py:222} INFO - ::endgroup::
