[2024-07-25T14:28:54.842-0300] {local_task_job_runner.py:120} INFO - ::group::Pre task execution logs
[2024-07-25T14:28:54.847-0300] {taskinstance.py:2076} INFO - Dependencies all met for dep_context=non-requeueable deps ti=<TaskInstance: Mercado_5m.get_5m_info scheduled__2024-07-25T14:25:00+00:00 [queued]>
[2024-07-25T14:28:54.850-0300] {taskinstance.py:2076} INFO - Dependencies all met for dep_context=requeueable deps ti=<TaskInstance: Mercado_5m.get_5m_info scheduled__2024-07-25T14:25:00+00:00 [queued]>
[2024-07-25T14:28:54.851-0300] {taskinstance.py:2306} INFO - Starting attempt 1 of 1
[2024-07-25T14:28:54.865-0300] {taskinstance.py:2330} INFO - Executing <Task(PythonOperator): get_5m_info> on 2024-07-25 14:25:00+00:00
[2024-07-25T14:28:54.868-0300] {standard_task_runner.py:64} INFO - Started process 2591709 to run task
[2024-07-25T14:28:54.869-0300] {standard_task_runner.py:90} INFO - Running: ['airflow', 'tasks', 'run', 'Mercado_5m', 'get_5m_info', 'scheduled__2024-07-25T14:25:00+00:00', '--job-id', '2140', '--raw', '--subdir', 'DAGS_FOLDER/mercado_dag.py', '--cfg-path', '/tmp/tmpxawseoyf']
[2024-07-25T14:28:54.870-0300] {standard_task_runner.py:91} INFO - Job 2140: Subtask get_5m_info
[2024-07-25T14:28:54.895-0300] {task_command.py:426} INFO - Running <TaskInstance: Mercado_5m.get_5m_info scheduled__2024-07-25T14:25:00+00:00 [running]> on host Galaxybook.
[2024-07-25T14:28:54.947-0300] {taskinstance.py:2648} INFO - Exporting env vars: AIRFLOW_CTX_DAG_OWNER='airflow' AIRFLOW_CTX_DAG_ID='Mercado_5m' AIRFLOW_CTX_TASK_ID='get_5m_info' AIRFLOW_CTX_EXECUTION_DATE='2024-07-25T14:25:00+00:00' AIRFLOW_CTX_TRY_NUMBER='1' AIRFLOW_CTX_DAG_RUN_ID='scheduled__2024-07-25T14:25:00+00:00'
[2024-07-25T14:28:54.947-0300] {taskinstance.py:430} INFO - ::endgroup::
[2024-07-25T14:28:54.953-0300] {taskinstance.py:441} INFO - ::group::Post task execution logs
[2024-07-25T14:28:54.953-0300] {taskinstance.py:2905} ERROR - Task failed with exception
Traceback (most recent call last):
  File "/home/hugoviana/Documentos/data_pipeline_airflow/.venv/lib/python3.12/site-packages/airflow/models/taskinstance.py", line 465, in _execute_task
    result = _execute_callable(context=context, **execute_callable_kwargs)
             ^^^^^^^^^^^^^^^^^^^^^^^^^^^^^^^^^^^^^^^^^^^^^^^^^^^^^^^^^^^^^
  File "/home/hugoviana/Documentos/data_pipeline_airflow/.venv/lib/python3.12/site-packages/airflow/models/taskinstance.py", line 432, in _execute_callable
    return execute_callable(context=context, **execute_callable_kwargs)
           ^^^^^^^^^^^^^^^^^^^^^^^^^^^^^^^^^^^^^^^^^^^^^^^^^^^^^^^^^^^^
  File "/home/hugoviana/Documentos/data_pipeline_airflow/.venv/lib/python3.12/site-packages/airflow/models/baseoperator.py", line 401, in wrapper
    return func(self, *args, **kwargs)
           ^^^^^^^^^^^^^^^^^^^^^^^^^^^
  File "/home/hugoviana/Documentos/data_pipeline_airflow/.venv/lib/python3.12/site-packages/airflow/operators/python.py", line 232, in execute
    context_merge(context, self.op_kwargs, templates_dict=self.templates_dict)
  File "/home/hugoviana/Documentos/data_pipeline_airflow/.venv/lib/python3.12/site-packages/airflow/utils/context.py", line 266, in context_merge
    context.update(*args, **kwargs)
  File "<frozen _collections_abc>", line 987, in update
ValueError: too many values to unpack (expected 2)
[2024-07-25T14:28:54.957-0300] {taskinstance.py:1206} INFO - Marking task as FAILED. dag_id=Mercado_5m, task_id=get_5m_info, run_id=scheduled__2024-07-25T14:25:00+00:00, execution_date=20240725T142500, start_date=20240725T172854, end_date=20240725T172854
[2024-07-25T14:28:54.967-0300] {standard_task_runner.py:110} ERROR - Failed to execute job 2140 for task get_5m_info (too many values to unpack (expected 2); 2591709)
[2024-07-25T14:28:55.003-0300] {local_task_job_runner.py:243} INFO - Task exited with return code 1
[2024-07-25T14:28:55.012-0300] {taskinstance.py:3503} INFO - 0 downstream tasks scheduled from follow-on schedule check
[2024-07-25T14:28:55.012-0300] {local_task_job_runner.py:222} INFO - ::endgroup::
[2024-07-25T14:30:46.644-0300] {local_task_job_runner.py:120} INFO - ::group::Pre task execution logs
[2024-07-25T14:30:46.650-0300] {taskinstance.py:2076} INFO - Dependencies all met for dep_context=non-requeueable deps ti=<TaskInstance: Mercado_5m.get_5m_info scheduled__2024-07-25T14:25:00+00:00 [queued]>
[2024-07-25T14:30:46.653-0300] {taskinstance.py:2076} INFO - Dependencies all met for dep_context=requeueable deps ti=<TaskInstance: Mercado_5m.get_5m_info scheduled__2024-07-25T14:25:00+00:00 [queued]>
[2024-07-25T14:30:46.653-0300] {taskinstance.py:2306} INFO - Starting attempt 1 of 1
[2024-07-25T14:30:46.671-0300] {taskinstance.py:2330} INFO - Executing <Task(PythonOperator): get_5m_info> on 2024-07-25 14:25:00+00:00
[2024-07-25T14:30:46.673-0300] {standard_task_runner.py:64} INFO - Started process 2593621 to run task
[2024-07-25T14:30:46.675-0300] {standard_task_runner.py:90} INFO - Running: ['airflow', 'tasks', 'run', 'Mercado_5m', 'get_5m_info', 'scheduled__2024-07-25T14:25:00+00:00', '--job-id', '2111', '--raw', '--subdir', 'DAGS_FOLDER/mercado_dag.py', '--cfg-path', '/tmp/tmp4qborxlq']
[2024-07-25T14:30:46.676-0300] {standard_task_runner.py:91} INFO - Job 2111: Subtask get_5m_info
[2024-07-25T14:30:46.718-0300] {task_command.py:426} INFO - Running <TaskInstance: Mercado_5m.get_5m_info scheduled__2024-07-25T14:25:00+00:00 [running]> on host Galaxybook.
[2024-07-25T14:30:46.778-0300] {taskinstance.py:2648} INFO - Exporting env vars: AIRFLOW_CTX_DAG_OWNER='airflow' AIRFLOW_CTX_DAG_ID='Mercado_5m' AIRFLOW_CTX_TASK_ID='get_5m_info' AIRFLOW_CTX_EXECUTION_DATE='2024-07-25T14:25:00+00:00' AIRFLOW_CTX_TRY_NUMBER='1' AIRFLOW_CTX_DAG_RUN_ID='scheduled__2024-07-25T14:25:00+00:00'
[2024-07-25T14:30:46.779-0300] {taskinstance.py:430} INFO - ::endgroup::
[2024-07-25T14:30:46.788-0300] {taskinstance.py:441} INFO - ::group::Post task execution logs
[2024-07-25T14:30:46.788-0300] {taskinstance.py:2905} ERROR - Task failed with exception
Traceback (most recent call last):
  File "/home/hugoviana/Documentos/data_pipeline_airflow/.venv/lib/python3.12/site-packages/airflow/models/taskinstance.py", line 465, in _execute_task
    result = _execute_callable(context=context, **execute_callable_kwargs)
             ^^^^^^^^^^^^^^^^^^^^^^^^^^^^^^^^^^^^^^^^^^^^^^^^^^^^^^^^^^^^^
  File "/home/hugoviana/Documentos/data_pipeline_airflow/.venv/lib/python3.12/site-packages/airflow/models/taskinstance.py", line 432, in _execute_callable
    return execute_callable(context=context, **execute_callable_kwargs)
           ^^^^^^^^^^^^^^^^^^^^^^^^^^^^^^^^^^^^^^^^^^^^^^^^^^^^^^^^^^^^
  File "/home/hugoviana/Documentos/data_pipeline_airflow/.venv/lib/python3.12/site-packages/airflow/models/baseoperator.py", line 401, in wrapper
    return func(self, *args, **kwargs)
           ^^^^^^^^^^^^^^^^^^^^^^^^^^^
  File "/home/hugoviana/Documentos/data_pipeline_airflow/.venv/lib/python3.12/site-packages/airflow/operators/python.py", line 232, in execute
    context_merge(context, self.op_kwargs, templates_dict=self.templates_dict)
  File "/home/hugoviana/Documentos/data_pipeline_airflow/.venv/lib/python3.12/site-packages/airflow/utils/context.py", line 266, in context_merge
    context.update(*args, **kwargs)
  File "<frozen _collections_abc>", line 987, in update
ValueError: too many values to unpack (expected 2)
[2024-07-25T14:30:46.792-0300] {taskinstance.py:1206} INFO - Marking task as FAILED. dag_id=Mercado_5m, task_id=get_5m_info, run_id=scheduled__2024-07-25T14:25:00+00:00, execution_date=20240725T142500, start_date=20240725T173046, end_date=20240725T173046
[2024-07-25T14:30:46.805-0300] {standard_task_runner.py:110} ERROR - Failed to execute job 2111 for task get_5m_info (too many values to unpack (expected 2); 2593621)
[2024-07-25T14:30:46.850-0300] {local_task_job_runner.py:243} INFO - Task exited with return code 1
[2024-07-25T14:30:46.857-0300] {taskinstance.py:3503} INFO - 0 downstream tasks scheduled from follow-on schedule check
[2024-07-25T14:30:46.858-0300] {local_task_job_runner.py:222} INFO - ::endgroup::
[2024-07-25T15:01:02.755-0300] {local_task_job_runner.py:120} INFO - ::group::Pre task execution logs
[2024-07-25T15:01:02.762-0300] {taskinstance.py:2076} INFO - Dependencies all met for dep_context=non-requeueable deps ti=<TaskInstance: Mercado_5m.get_5m_info scheduled__2024-07-25T14:25:00+00:00 [queued]>
[2024-07-25T15:01:02.765-0300] {taskinstance.py:2076} INFO - Dependencies all met for dep_context=requeueable deps ti=<TaskInstance: Mercado_5m.get_5m_info scheduled__2024-07-25T14:25:00+00:00 [queued]>
[2024-07-25T15:01:02.766-0300] {taskinstance.py:2306} INFO - Starting attempt 1 of 1
[2024-07-25T15:01:02.781-0300] {taskinstance.py:2330} INFO - Executing <Task(PythonOperator): get_5m_info> on 2024-07-25 14:25:00+00:00
[2024-07-25T15:01:02.783-0300] {standard_task_runner.py:64} INFO - Started process 2620467 to run task
[2024-07-25T15:01:02.785-0300] {standard_task_runner.py:90} INFO - Running: ['airflow', 'tasks', 'run', 'Mercado_5m', 'get_5m_info', 'scheduled__2024-07-25T14:25:00+00:00', '--job-id', '2485', '--raw', '--subdir', 'DAGS_FOLDER/mercado_dag.py', '--cfg-path', '/tmp/tmpsys7t_ht']
[2024-07-25T15:01:02.786-0300] {standard_task_runner.py:91} INFO - Job 2485: Subtask get_5m_info
[2024-07-25T15:01:02.819-0300] {task_command.py:426} INFO - Running <TaskInstance: Mercado_5m.get_5m_info scheduled__2024-07-25T14:25:00+00:00 [running]> on host Galaxybook.
[2024-07-25T15:01:02.880-0300] {taskinstance.py:2648} INFO - Exporting env vars: AIRFLOW_CTX_DAG_OWNER='airflow' AIRFLOW_CTX_DAG_ID='Mercado_5m' AIRFLOW_CTX_TASK_ID='get_5m_info' AIRFLOW_CTX_EXECUTION_DATE='2024-07-25T14:25:00+00:00' AIRFLOW_CTX_TRY_NUMBER='1' AIRFLOW_CTX_DAG_RUN_ID='scheduled__2024-07-25T14:25:00+00:00'
[2024-07-25T15:01:02.881-0300] {taskinstance.py:430} INFO - ::endgroup::
[2024-07-25T15:01:02.956-0300] {base.py:84} INFO - Using connection ID 'mercado_default' for task execution.
[2024-07-25T15:01:02.956-0300] {mercado_hook.py:31} INFO - URL: https://api.mercadobitcoin.net/api/v4/candles?symbol=BTC-BRL&resolution=5m&to=1721928600&from=1721928300
[2024-07-25T15:01:03.227-0300] {python.py:237} INFO - Done. Returned value was: None
[2024-07-25T15:01:03.228-0300] {taskinstance.py:441} INFO - ::group::Post task execution logs
[2024-07-25T15:01:03.230-0300] {taskinstance.py:1206} INFO - Marking task as SUCCESS. dag_id=Mercado_5m, task_id=get_5m_info, run_id=scheduled__2024-07-25T14:25:00+00:00, execution_date=20240725T142500, start_date=20240725T180102, end_date=20240725T180103
[2024-07-25T15:01:03.284-0300] {local_task_job_runner.py:243} INFO - Task exited with return code 0
[2024-07-25T15:01:03.292-0300] {taskinstance.py:3503} INFO - 0 downstream tasks scheduled from follow-on schedule check
[2024-07-25T15:01:03.292-0300] {local_task_job_runner.py:222} INFO - ::endgroup::
