[2024-07-25T14:28:37.295-0300] {local_task_job_runner.py:120} INFO - ::group::Pre task execution logs
[2024-07-25T14:28:37.301-0300] {taskinstance.py:2076} INFO - Dependencies all met for dep_context=non-requeueable deps ti=<TaskInstance: Mercado_5m.get_5m_info scheduled__2024-07-25T13:55:00+00:00 [queued]>
[2024-07-25T14:28:37.304-0300] {taskinstance.py:2076} INFO - Dependencies all met for dep_context=requeueable deps ti=<TaskInstance: Mercado_5m.get_5m_info scheduled__2024-07-25T13:55:00+00:00 [queued]>
[2024-07-25T14:28:37.305-0300] {taskinstance.py:2306} INFO - Starting attempt 1 of 1
[2024-07-25T14:28:37.317-0300] {taskinstance.py:2330} INFO - Executing <Task(PythonOperator): get_5m_info> on 2024-07-25 13:55:00+00:00
[2024-07-25T14:28:37.318-0300] {standard_task_runner.py:64} INFO - Started process 2591410 to run task
[2024-07-25T14:28:37.321-0300] {standard_task_runner.py:90} INFO - Running: ['airflow', 'tasks', 'run', 'Mercado_5m', 'get_5m_info', 'scheduled__2024-07-25T13:55:00+00:00', '--job-id', '2129', '--raw', '--subdir', 'DAGS_FOLDER/mercado_dag.py', '--cfg-path', '/tmp/tmpvycoqxag']
[2024-07-25T14:28:37.321-0300] {standard_task_runner.py:91} INFO - Job 2129: Subtask get_5m_info
[2024-07-25T14:28:37.350-0300] {task_command.py:426} INFO - Running <TaskInstance: Mercado_5m.get_5m_info scheduled__2024-07-25T13:55:00+00:00 [running]> on host Galaxybook.
[2024-07-25T14:28:37.392-0300] {taskinstance.py:2648} INFO - Exporting env vars: AIRFLOW_CTX_DAG_OWNER='airflow' AIRFLOW_CTX_DAG_ID='Mercado_5m' AIRFLOW_CTX_TASK_ID='get_5m_info' AIRFLOW_CTX_EXECUTION_DATE='2024-07-25T13:55:00+00:00' AIRFLOW_CTX_TRY_NUMBER='1' AIRFLOW_CTX_DAG_RUN_ID='scheduled__2024-07-25T13:55:00+00:00'
[2024-07-25T14:28:37.393-0300] {taskinstance.py:430} INFO - ::endgroup::
[2024-07-25T14:28:37.400-0300] {taskinstance.py:441} INFO - ::group::Post task execution logs
[2024-07-25T14:28:37.400-0300] {taskinstance.py:2905} ERROR - Task failed with exception
Traceback (most recent call last):
  File "/home/hugoviana/Documentos/data_pipeline_airflow/.venv/lib/python3.12/site-packages/airflow/models/taskinstance.py", line 465, in _execute_task
    result = _execute_callable(context=context, **execute_callable_kwargs)
             ^^^^^^^^^^^^^^^^^^^^^^^^^^^^^^^^^^^^^^^^^^^^^^^^^^^^^^^^^^^^^
  File "/home/hugoviana/Documentos/data_pipeline_airflow/.venv/lib/python3.12/site-packages/airflow/models/taskinstance.py", line 432, in _execute_callable
    return execute_callable(context=context, **execute_callable_kwargs)
           ^^^^^^^^^^^^^^^^^^^^^^^^^^^^^^^^^^^^^^^^^^^^^^^^^^^^^^^^^^^^
  File "/home/hugoviana/Documentos/data_pipeline_airflow/.venv/lib/python3.12/site-packages/airflow/models/baseoperator.py", line 401, in wrapper
    return func(self, *args, **kwargs)
           ^^^^^^^^^^^^^^^^^^^^^^^^^^^
  File "/home/hugoviana/Documentos/data_pipeline_airflow/.venv/lib/python3.12/site-packages/airflow/operators/python.py", line 232, in execute
    context_merge(context, self.op_kwargs, templates_dict=self.templates_dict)
  File "/home/hugoviana/Documentos/data_pipeline_airflow/.venv/lib/python3.12/site-packages/airflow/utils/context.py", line 266, in context_merge
    context.update(*args, **kwargs)
  File "<frozen _collections_abc>", line 987, in update
ValueError: too many values to unpack (expected 2)
[2024-07-25T14:28:37.404-0300] {taskinstance.py:1206} INFO - Marking task as FAILED. dag_id=Mercado_5m, task_id=get_5m_info, run_id=scheduled__2024-07-25T13:55:00+00:00, execution_date=20240725T135500, start_date=20240725T172837, end_date=20240725T172837
[2024-07-25T14:28:37.416-0300] {standard_task_runner.py:110} ERROR - Failed to execute job 2129 for task get_5m_info (too many values to unpack (expected 2); 2591410)
[2024-07-25T14:28:37.454-0300] {local_task_job_runner.py:243} INFO - Task exited with return code 1
[2024-07-25T14:28:37.462-0300] {taskinstance.py:3503} INFO - 0 downstream tasks scheduled from follow-on schedule check
[2024-07-25T14:28:37.463-0300] {local_task_job_runner.py:222} INFO - ::endgroup::
[2024-07-25T14:30:36.102-0300] {local_task_job_runner.py:120} INFO - ::group::Pre task execution logs
[2024-07-25T14:30:36.108-0300] {taskinstance.py:2076} INFO - Dependencies all met for dep_context=non-requeueable deps ti=<TaskInstance: Mercado_5m.get_5m_info scheduled__2024-07-25T13:55:00+00:00 [queued]>
[2024-07-25T14:30:36.111-0300] {taskinstance.py:2076} INFO - Dependencies all met for dep_context=requeueable deps ti=<TaskInstance: Mercado_5m.get_5m_info scheduled__2024-07-25T13:55:00+00:00 [queued]>
[2024-07-25T14:30:36.111-0300] {taskinstance.py:2306} INFO - Starting attempt 1 of 1
[2024-07-25T14:30:36.125-0300] {taskinstance.py:2330} INFO - Executing <Task(PythonOperator): get_5m_info> on 2024-07-25 13:55:00+00:00
[2024-07-25T14:30:36.127-0300] {standard_task_runner.py:64} INFO - Started process 2593459 to run task
[2024-07-25T14:30:36.129-0300] {standard_task_runner.py:90} INFO - Running: ['airflow', 'tasks', 'run', 'Mercado_5m', 'get_5m_info', 'scheduled__2024-07-25T13:55:00+00:00', '--job-id', '2105', '--raw', '--subdir', 'DAGS_FOLDER/mercado_dag.py', '--cfg-path', '/tmp/tmps34g5__g']
[2024-07-25T14:30:36.130-0300] {standard_task_runner.py:91} INFO - Job 2105: Subtask get_5m_info
[2024-07-25T14:30:36.156-0300] {task_command.py:426} INFO - Running <TaskInstance: Mercado_5m.get_5m_info scheduled__2024-07-25T13:55:00+00:00 [running]> on host Galaxybook.
[2024-07-25T14:30:36.202-0300] {taskinstance.py:2648} INFO - Exporting env vars: AIRFLOW_CTX_DAG_OWNER='airflow' AIRFLOW_CTX_DAG_ID='Mercado_5m' AIRFLOW_CTX_TASK_ID='get_5m_info' AIRFLOW_CTX_EXECUTION_DATE='2024-07-25T13:55:00+00:00' AIRFLOW_CTX_TRY_NUMBER='1' AIRFLOW_CTX_DAG_RUN_ID='scheduled__2024-07-25T13:55:00+00:00'
[2024-07-25T14:30:36.202-0300] {taskinstance.py:430} INFO - ::endgroup::
[2024-07-25T14:30:36.209-0300] {taskinstance.py:441} INFO - ::group::Post task execution logs
[2024-07-25T14:30:36.209-0300] {taskinstance.py:2905} ERROR - Task failed with exception
Traceback (most recent call last):
  File "/home/hugoviana/Documentos/data_pipeline_airflow/.venv/lib/python3.12/site-packages/airflow/models/taskinstance.py", line 465, in _execute_task
    result = _execute_callable(context=context, **execute_callable_kwargs)
             ^^^^^^^^^^^^^^^^^^^^^^^^^^^^^^^^^^^^^^^^^^^^^^^^^^^^^^^^^^^^^
  File "/home/hugoviana/Documentos/data_pipeline_airflow/.venv/lib/python3.12/site-packages/airflow/models/taskinstance.py", line 432, in _execute_callable
    return execute_callable(context=context, **execute_callable_kwargs)
           ^^^^^^^^^^^^^^^^^^^^^^^^^^^^^^^^^^^^^^^^^^^^^^^^^^^^^^^^^^^^
  File "/home/hugoviana/Documentos/data_pipeline_airflow/.venv/lib/python3.12/site-packages/airflow/models/baseoperator.py", line 401, in wrapper
    return func(self, *args, **kwargs)
           ^^^^^^^^^^^^^^^^^^^^^^^^^^^
  File "/home/hugoviana/Documentos/data_pipeline_airflow/.venv/lib/python3.12/site-packages/airflow/operators/python.py", line 232, in execute
    context_merge(context, self.op_kwargs, templates_dict=self.templates_dict)
  File "/home/hugoviana/Documentos/data_pipeline_airflow/.venv/lib/python3.12/site-packages/airflow/utils/context.py", line 266, in context_merge
    context.update(*args, **kwargs)
  File "<frozen _collections_abc>", line 987, in update
ValueError: too many values to unpack (expected 2)
[2024-07-25T14:30:36.212-0300] {taskinstance.py:1206} INFO - Marking task as FAILED. dag_id=Mercado_5m, task_id=get_5m_info, run_id=scheduled__2024-07-25T13:55:00+00:00, execution_date=20240725T135500, start_date=20240725T173036, end_date=20240725T173036
[2024-07-25T14:30:36.221-0300] {standard_task_runner.py:110} ERROR - Failed to execute job 2105 for task get_5m_info (too many values to unpack (expected 2); 2593459)
[2024-07-25T14:30:36.262-0300] {local_task_job_runner.py:243} INFO - Task exited with return code 1
[2024-07-25T14:30:36.269-0300] {taskinstance.py:3503} INFO - 0 downstream tasks scheduled from follow-on schedule check
[2024-07-25T14:30:36.269-0300] {local_task_job_runner.py:222} INFO - ::endgroup::
[2024-07-25T15:00:51.770-0300] {local_task_job_runner.py:120} INFO - ::group::Pre task execution logs
[2024-07-25T15:00:51.775-0300] {taskinstance.py:2076} INFO - Dependencies all met for dep_context=non-requeueable deps ti=<TaskInstance: Mercado_5m.get_5m_info scheduled__2024-07-25T13:55:00+00:00 [queued]>
[2024-07-25T15:00:51.778-0300] {taskinstance.py:2076} INFO - Dependencies all met for dep_context=requeueable deps ti=<TaskInstance: Mercado_5m.get_5m_info scheduled__2024-07-25T13:55:00+00:00 [queued]>
[2024-07-25T15:00:51.778-0300] {taskinstance.py:2306} INFO - Starting attempt 1 of 1
[2024-07-25T15:00:51.793-0300] {taskinstance.py:2330} INFO - Executing <Task(PythonOperator): get_5m_info> on 2024-07-25 13:55:00+00:00
[2024-07-25T15:00:51.795-0300] {standard_task_runner.py:64} INFO - Started process 2620296 to run task
[2024-07-25T15:00:51.797-0300] {standard_task_runner.py:90} INFO - Running: ['airflow', 'tasks', 'run', 'Mercado_5m', 'get_5m_info', 'scheduled__2024-07-25T13:55:00+00:00', '--job-id', '2479', '--raw', '--subdir', 'DAGS_FOLDER/mercado_dag.py', '--cfg-path', '/tmp/tmphyyd7h9b']
[2024-07-25T15:00:51.798-0300] {standard_task_runner.py:91} INFO - Job 2479: Subtask get_5m_info
[2024-07-25T15:00:51.824-0300] {task_command.py:426} INFO - Running <TaskInstance: Mercado_5m.get_5m_info scheduled__2024-07-25T13:55:00+00:00 [running]> on host Galaxybook.
[2024-07-25T15:00:51.877-0300] {taskinstance.py:2648} INFO - Exporting env vars: AIRFLOW_CTX_DAG_OWNER='airflow' AIRFLOW_CTX_DAG_ID='Mercado_5m' AIRFLOW_CTX_TASK_ID='get_5m_info' AIRFLOW_CTX_EXECUTION_DATE='2024-07-25T13:55:00+00:00' AIRFLOW_CTX_TRY_NUMBER='1' AIRFLOW_CTX_DAG_RUN_ID='scheduled__2024-07-25T13:55:00+00:00'
[2024-07-25T15:00:51.878-0300] {taskinstance.py:430} INFO - ::endgroup::
[2024-07-25T15:00:51.941-0300] {base.py:84} INFO - Using connection ID 'mercado_default' for task execution.
[2024-07-25T15:00:51.942-0300] {mercado_hook.py:31} INFO - URL: https://api.mercadobitcoin.net/api/v4/candles?symbol=BTC-BRL&resolution=5m&to=1721926800&from=1721926500
[2024-07-25T15:00:52.293-0300] {python.py:237} INFO - Done. Returned value was: None
[2024-07-25T15:00:52.294-0300] {taskinstance.py:441} INFO - ::group::Post task execution logs
[2024-07-25T15:00:52.297-0300] {taskinstance.py:1206} INFO - Marking task as SUCCESS. dag_id=Mercado_5m, task_id=get_5m_info, run_id=scheduled__2024-07-25T13:55:00+00:00, execution_date=20240725T135500, start_date=20240725T180051, end_date=20240725T180052
[2024-07-25T15:00:52.341-0300] {local_task_job_runner.py:243} INFO - Task exited with return code 0
[2024-07-25T15:00:52.348-0300] {taskinstance.py:3503} INFO - 0 downstream tasks scheduled from follow-on schedule check
[2024-07-25T15:00:52.348-0300] {local_task_job_runner.py:222} INFO - ::endgroup::
