[2024-07-25T12:49:02.080-0300] {local_task_job_runner.py:120} INFO - ::group::Pre task execution logs
[2024-07-25T12:49:02.085-0300] {taskinstance.py:2076} INFO - Dependencies all met for dep_context=non-requeueable deps ti=<TaskInstance: Binance_5m.get_5m_info manual__2024-07-25T15:49:00.738796+00:00 [queued]>
[2024-07-25T12:49:02.089-0300] {taskinstance.py:2076} INFO - Dependencies all met for dep_context=requeueable deps ti=<TaskInstance: Binance_5m.get_5m_info manual__2024-07-25T15:49:00.738796+00:00 [queued]>
[2024-07-25T12:49:02.089-0300] {taskinstance.py:2306} INFO - Starting attempt 1 of 1
[2024-07-25T12:49:02.104-0300] {taskinstance.py:2330} INFO - Executing <Task(PythonOperator): get_5m_info> on 2024-07-25 15:49:00.738796+00:00
[2024-07-25T12:49:02.106-0300] {standard_task_runner.py:64} INFO - Started process 2542254 to run task
[2024-07-25T12:49:02.107-0300] {standard_task_runner.py:90} INFO - Running: ['airflow', 'tasks', 'run', 'Binance_5m', 'get_5m_info', 'manual__2024-07-25T15:49:00.738796+00:00', '--job-id', '2067', '--raw', '--subdir', 'DAGS_FOLDER/binance_dag.py', '--cfg-path', '/tmp/tmpdet4a5mh']
[2024-07-25T12:49:02.108-0300] {standard_task_runner.py:91} INFO - Job 2067: Subtask get_5m_info
[2024-07-25T12:49:02.133-0300] {task_command.py:426} INFO - Running <TaskInstance: Binance_5m.get_5m_info manual__2024-07-25T15:49:00.738796+00:00 [running]> on host Galaxybook.
[2024-07-25T12:49:02.187-0300] {taskinstance.py:2648} INFO - Exporting env vars: AIRFLOW_CTX_DAG_OWNER='airflow' AIRFLOW_CTX_DAG_ID='Binance_5m' AIRFLOW_CTX_TASK_ID='get_5m_info' AIRFLOW_CTX_EXECUTION_DATE='2024-07-25T15:49:00.738796+00:00' AIRFLOW_CTX_TRY_NUMBER='1' AIRFLOW_CTX_DAG_RUN_ID='manual__2024-07-25T15:49:00.738796+00:00'
[2024-07-25T12:49:02.188-0300] {taskinstance.py:430} INFO - ::endgroup::
[2024-07-25T12:49:02.197-0300] {taskinstance.py:441} INFO - ::group::Post task execution logs
[2024-07-25T12:49:02.197-0300] {taskinstance.py:2905} ERROR - Task failed with exception
Traceback (most recent call last):
  File "/home/hugoviana/Documentos/data_pipeline_airflow/.venv/lib/python3.12/site-packages/airflow/models/taskinstance.py", line 465, in _execute_task
    result = _execute_callable(context=context, **execute_callable_kwargs)
             ^^^^^^^^^^^^^^^^^^^^^^^^^^^^^^^^^^^^^^^^^^^^^^^^^^^^^^^^^^^^^
  File "/home/hugoviana/Documentos/data_pipeline_airflow/.venv/lib/python3.12/site-packages/airflow/models/taskinstance.py", line 432, in _execute_callable
    return execute_callable(context=context, **execute_callable_kwargs)
           ^^^^^^^^^^^^^^^^^^^^^^^^^^^^^^^^^^^^^^^^^^^^^^^^^^^^^^^^^^^^
  File "/home/hugoviana/Documentos/data_pipeline_airflow/.venv/lib/python3.12/site-packages/airflow/models/baseoperator.py", line 401, in wrapper
    return func(self, *args, **kwargs)
           ^^^^^^^^^^^^^^^^^^^^^^^^^^^
  File "/home/hugoviana/Documentos/data_pipeline_airflow/.venv/lib/python3.12/site-packages/airflow/operators/python.py", line 233, in execute
    self.op_kwargs = self.determine_kwargs(context)
                     ^^^^^^^^^^^^^^^^^^^^^^^^^^^^^^
  File "/home/hugoviana/Documentos/data_pipeline_airflow/.venv/lib/python3.12/site-packages/airflow/operators/python.py", line 244, in determine_kwargs
    return KeywordParameters.determine(self.python_callable, self.op_args, context).unpacking()
           ^^^^^^^^^^^^^^^^^^^^^^^^^^^^^^^^^^^^^^^^^^^^^^^^^^^^^^^^^^^^^^^^^^^^^^^^
  File "/home/hugoviana/Documentos/data_pipeline_airflow/.venv/lib/python3.12/site-packages/airflow/utils/operator_helpers.py", line 163, in determine
    raise ValueError(f"The key {name!r} in args is a part of kwargs and therefore reserved.")
ValueError: The key 'data_interval_end' in args is a part of kwargs and therefore reserved.
[2024-07-25T12:49:02.269-0300] {taskinstance.py:1206} INFO - Marking task as FAILED. dag_id=Binance_5m, task_id=get_5m_info, run_id=manual__2024-07-25T15:49:00.738796+00:00, execution_date=20240725T154900, start_date=20240725T154902, end_date=20240725T154902
[2024-07-25T12:49:02.283-0300] {standard_task_runner.py:110} ERROR - Failed to execute job 2067 for task get_5m_info (The key 'data_interval_end' in args is a part of kwargs and therefore reserved.; 2542254)
[2024-07-25T12:49:02.324-0300] {local_task_job_runner.py:243} INFO - Task exited with return code 1
[2024-07-25T12:49:02.330-0300] {taskinstance.py:3503} INFO - 0 downstream tasks scheduled from follow-on schedule check
[2024-07-25T12:49:02.331-0300] {local_task_job_runner.py:222} INFO - ::endgroup::
