[2024-07-25T14:28:43.157-0300] {local_task_job_runner.py:120} INFO - ::group::Pre task execution logs
[2024-07-25T14:28:43.164-0300] {taskinstance.py:2076} INFO - Dependencies all met for dep_context=non-requeueable deps ti=<TaskInstance: Mercado_5m.get_5m_info scheduled__2024-07-25T14:05:00+00:00 [queued]>
[2024-07-25T14:28:43.167-0300] {taskinstance.py:2076} INFO - Dependencies all met for dep_context=requeueable deps ti=<TaskInstance: Mercado_5m.get_5m_info scheduled__2024-07-25T14:05:00+00:00 [queued]>
[2024-07-25T14:28:43.168-0300] {taskinstance.py:2306} INFO - Starting attempt 1 of 1
[2024-07-25T14:28:43.182-0300] {taskinstance.py:2330} INFO - Executing <Task(PythonOperator): get_5m_info> on 2024-07-25 14:05:00+00:00
[2024-07-25T14:28:43.184-0300] {standard_task_runner.py:64} INFO - Started process 2591499 to run task
[2024-07-25T14:28:43.186-0300] {standard_task_runner.py:90} INFO - Running: ['airflow', 'tasks', 'run', 'Mercado_5m', 'get_5m_info', 'scheduled__2024-07-25T14:05:00+00:00', '--job-id', '2133', '--raw', '--subdir', 'DAGS_FOLDER/mercado_dag.py', '--cfg-path', '/tmp/tmp88s7kj99']
[2024-07-25T14:28:43.187-0300] {standard_task_runner.py:91} INFO - Job 2133: Subtask get_5m_info
[2024-07-25T14:28:43.215-0300] {task_command.py:426} INFO - Running <TaskInstance: Mercado_5m.get_5m_info scheduled__2024-07-25T14:05:00+00:00 [running]> on host Galaxybook.
[2024-07-25T14:28:43.264-0300] {taskinstance.py:2648} INFO - Exporting env vars: AIRFLOW_CTX_DAG_OWNER='airflow' AIRFLOW_CTX_DAG_ID='Mercado_5m' AIRFLOW_CTX_TASK_ID='get_5m_info' AIRFLOW_CTX_EXECUTION_DATE='2024-07-25T14:05:00+00:00' AIRFLOW_CTX_TRY_NUMBER='1' AIRFLOW_CTX_DAG_RUN_ID='scheduled__2024-07-25T14:05:00+00:00'
[2024-07-25T14:28:43.265-0300] {taskinstance.py:430} INFO - ::endgroup::
[2024-07-25T14:28:43.272-0300] {taskinstance.py:441} INFO - ::group::Post task execution logs
[2024-07-25T14:28:43.272-0300] {taskinstance.py:2905} ERROR - Task failed with exception
Traceback (most recent call last):
  File "/home/hugoviana/Documentos/data_pipeline_airflow/.venv/lib/python3.12/site-packages/airflow/models/taskinstance.py", line 465, in _execute_task
    result = _execute_callable(context=context, **execute_callable_kwargs)
             ^^^^^^^^^^^^^^^^^^^^^^^^^^^^^^^^^^^^^^^^^^^^^^^^^^^^^^^^^^^^^
  File "/home/hugoviana/Documentos/data_pipeline_airflow/.venv/lib/python3.12/site-packages/airflow/models/taskinstance.py", line 432, in _execute_callable
    return execute_callable(context=context, **execute_callable_kwargs)
           ^^^^^^^^^^^^^^^^^^^^^^^^^^^^^^^^^^^^^^^^^^^^^^^^^^^^^^^^^^^^
  File "/home/hugoviana/Documentos/data_pipeline_airflow/.venv/lib/python3.12/site-packages/airflow/models/baseoperator.py", line 401, in wrapper
    return func(self, *args, **kwargs)
           ^^^^^^^^^^^^^^^^^^^^^^^^^^^
  File "/home/hugoviana/Documentos/data_pipeline_airflow/.venv/lib/python3.12/site-packages/airflow/operators/python.py", line 232, in execute
    context_merge(context, self.op_kwargs, templates_dict=self.templates_dict)
  File "/home/hugoviana/Documentos/data_pipeline_airflow/.venv/lib/python3.12/site-packages/airflow/utils/context.py", line 266, in context_merge
    context.update(*args, **kwargs)
  File "<frozen _collections_abc>", line 987, in update
ValueError: too many values to unpack (expected 2)
[2024-07-25T14:28:43.277-0300] {taskinstance.py:1206} INFO - Marking task as FAILED. dag_id=Mercado_5m, task_id=get_5m_info, run_id=scheduled__2024-07-25T14:05:00+00:00, execution_date=20240725T140500, start_date=20240725T172843, end_date=20240725T172843
[2024-07-25T14:28:43.288-0300] {standard_task_runner.py:110} ERROR - Failed to execute job 2133 for task get_5m_info (too many values to unpack (expected 2); 2591499)
[2024-07-25T14:28:43.319-0300] {local_task_job_runner.py:243} INFO - Task exited with return code 1
[2024-07-25T14:28:43.326-0300] {taskinstance.py:3503} INFO - 0 downstream tasks scheduled from follow-on schedule check
[2024-07-25T14:28:43.326-0300] {local_task_job_runner.py:222} INFO - ::endgroup::
[2024-07-25T14:30:38.932-0300] {local_task_job_runner.py:120} INFO - ::group::Pre task execution logs
[2024-07-25T14:30:38.940-0300] {taskinstance.py:2076} INFO - Dependencies all met for dep_context=non-requeueable deps ti=<TaskInstance: Mercado_5m.get_5m_info scheduled__2024-07-25T14:05:00+00:00 [queued]>
[2024-07-25T14:30:38.946-0300] {taskinstance.py:2076} INFO - Dependencies all met for dep_context=requeueable deps ti=<TaskInstance: Mercado_5m.get_5m_info scheduled__2024-07-25T14:05:00+00:00 [queued]>
[2024-07-25T14:30:38.946-0300] {taskinstance.py:2306} INFO - Starting attempt 1 of 1
[2024-07-25T14:30:38.961-0300] {taskinstance.py:2330} INFO - Executing <Task(PythonOperator): get_5m_info> on 2024-07-25 14:05:00+00:00
[2024-07-25T14:30:38.964-0300] {standard_task_runner.py:64} INFO - Started process 2593472 to run task
[2024-07-25T14:30:38.966-0300] {standard_task_runner.py:90} INFO - Running: ['airflow', 'tasks', 'run', 'Mercado_5m', 'get_5m_info', 'scheduled__2024-07-25T14:05:00+00:00', '--job-id', '2107', '--raw', '--subdir', 'DAGS_FOLDER/mercado_dag.py', '--cfg-path', '/tmp/tmpebcoir0l']
[2024-07-25T14:30:38.967-0300] {standard_task_runner.py:91} INFO - Job 2107: Subtask get_5m_info
[2024-07-25T14:30:38.998-0300] {task_command.py:426} INFO - Running <TaskInstance: Mercado_5m.get_5m_info scheduled__2024-07-25T14:05:00+00:00 [running]> on host Galaxybook.
[2024-07-25T14:30:39.046-0300] {taskinstance.py:2648} INFO - Exporting env vars: AIRFLOW_CTX_DAG_OWNER='airflow' AIRFLOW_CTX_DAG_ID='Mercado_5m' AIRFLOW_CTX_TASK_ID='get_5m_info' AIRFLOW_CTX_EXECUTION_DATE='2024-07-25T14:05:00+00:00' AIRFLOW_CTX_TRY_NUMBER='1' AIRFLOW_CTX_DAG_RUN_ID='scheduled__2024-07-25T14:05:00+00:00'
[2024-07-25T14:30:39.046-0300] {taskinstance.py:430} INFO - ::endgroup::
[2024-07-25T14:30:39.053-0300] {taskinstance.py:441} INFO - ::group::Post task execution logs
[2024-07-25T14:30:39.053-0300] {taskinstance.py:2905} ERROR - Task failed with exception
Traceback (most recent call last):
  File "/home/hugoviana/Documentos/data_pipeline_airflow/.venv/lib/python3.12/site-packages/airflow/models/taskinstance.py", line 465, in _execute_task
    result = _execute_callable(context=context, **execute_callable_kwargs)
             ^^^^^^^^^^^^^^^^^^^^^^^^^^^^^^^^^^^^^^^^^^^^^^^^^^^^^^^^^^^^^
  File "/home/hugoviana/Documentos/data_pipeline_airflow/.venv/lib/python3.12/site-packages/airflow/models/taskinstance.py", line 432, in _execute_callable
    return execute_callable(context=context, **execute_callable_kwargs)
           ^^^^^^^^^^^^^^^^^^^^^^^^^^^^^^^^^^^^^^^^^^^^^^^^^^^^^^^^^^^^
  File "/home/hugoviana/Documentos/data_pipeline_airflow/.venv/lib/python3.12/site-packages/airflow/models/baseoperator.py", line 401, in wrapper
    return func(self, *args, **kwargs)
           ^^^^^^^^^^^^^^^^^^^^^^^^^^^
  File "/home/hugoviana/Documentos/data_pipeline_airflow/.venv/lib/python3.12/site-packages/airflow/operators/python.py", line 232, in execute
    context_merge(context, self.op_kwargs, templates_dict=self.templates_dict)
  File "/home/hugoviana/Documentos/data_pipeline_airflow/.venv/lib/python3.12/site-packages/airflow/utils/context.py", line 266, in context_merge
    context.update(*args, **kwargs)
  File "<frozen _collections_abc>", line 987, in update
ValueError: too many values to unpack (expected 2)
[2024-07-25T14:30:39.057-0300] {taskinstance.py:1206} INFO - Marking task as FAILED. dag_id=Mercado_5m, task_id=get_5m_info, run_id=scheduled__2024-07-25T14:05:00+00:00, execution_date=20240725T140500, start_date=20240725T173038, end_date=20240725T173039
[2024-07-25T14:30:39.068-0300] {standard_task_runner.py:110} ERROR - Failed to execute job 2107 for task get_5m_info (too many values to unpack (expected 2); 2593472)
[2024-07-25T14:30:39.101-0300] {local_task_job_runner.py:243} INFO - Task exited with return code 1
[2024-07-25T14:30:39.109-0300] {taskinstance.py:3503} INFO - 0 downstream tasks scheduled from follow-on schedule check
[2024-07-25T14:30:39.109-0300] {local_task_job_runner.py:222} INFO - ::endgroup::
[2024-07-25T15:00:55.312-0300] {local_task_job_runner.py:120} INFO - ::group::Pre task execution logs
[2024-07-25T15:00:55.318-0300] {taskinstance.py:2076} INFO - Dependencies all met for dep_context=non-requeueable deps ti=<TaskInstance: Mercado_5m.get_5m_info scheduled__2024-07-25T14:05:00+00:00 [queued]>
[2024-07-25T15:00:55.322-0300] {taskinstance.py:2076} INFO - Dependencies all met for dep_context=requeueable deps ti=<TaskInstance: Mercado_5m.get_5m_info scheduled__2024-07-25T14:05:00+00:00 [queued]>
[2024-07-25T15:00:55.322-0300] {taskinstance.py:2306} INFO - Starting attempt 1 of 1
[2024-07-25T15:00:55.335-0300] {taskinstance.py:2330} INFO - Executing <Task(PythonOperator): get_5m_info> on 2024-07-25 14:05:00+00:00
[2024-07-25T15:00:55.337-0300] {standard_task_runner.py:64} INFO - Started process 2620375 to run task
[2024-07-25T15:00:55.339-0300] {standard_task_runner.py:90} INFO - Running: ['airflow', 'tasks', 'run', 'Mercado_5m', 'get_5m_info', 'scheduled__2024-07-25T14:05:00+00:00', '--job-id', '2481', '--raw', '--subdir', 'DAGS_FOLDER/mercado_dag.py', '--cfg-path', '/tmp/tmp595omiid']
[2024-07-25T15:00:55.340-0300] {standard_task_runner.py:91} INFO - Job 2481: Subtask get_5m_info
[2024-07-25T15:00:55.368-0300] {task_command.py:426} INFO - Running <TaskInstance: Mercado_5m.get_5m_info scheduled__2024-07-25T14:05:00+00:00 [running]> on host Galaxybook.
[2024-07-25T15:00:55.419-0300] {taskinstance.py:2648} INFO - Exporting env vars: AIRFLOW_CTX_DAG_OWNER='airflow' AIRFLOW_CTX_DAG_ID='Mercado_5m' AIRFLOW_CTX_TASK_ID='get_5m_info' AIRFLOW_CTX_EXECUTION_DATE='2024-07-25T14:05:00+00:00' AIRFLOW_CTX_TRY_NUMBER='1' AIRFLOW_CTX_DAG_RUN_ID='scheduled__2024-07-25T14:05:00+00:00'
[2024-07-25T15:00:55.419-0300] {taskinstance.py:430} INFO - ::endgroup::
[2024-07-25T15:00:55.480-0300] {base.py:84} INFO - Using connection ID 'mercado_default' for task execution.
[2024-07-25T15:00:55.480-0300] {mercado_hook.py:31} INFO - URL: https://api.mercadobitcoin.net/api/v4/candles?symbol=BTC-BRL&resolution=5m&to=1721927400&from=1721927100
[2024-07-25T15:00:55.757-0300] {python.py:237} INFO - Done. Returned value was: None
[2024-07-25T15:00:55.758-0300] {taskinstance.py:441} INFO - ::group::Post task execution logs
[2024-07-25T15:00:55.761-0300] {taskinstance.py:1206} INFO - Marking task as SUCCESS. dag_id=Mercado_5m, task_id=get_5m_info, run_id=scheduled__2024-07-25T14:05:00+00:00, execution_date=20240725T140500, start_date=20240725T180055, end_date=20240725T180055
[2024-07-25T15:00:55.798-0300] {local_task_job_runner.py:243} INFO - Task exited with return code 0
[2024-07-25T15:00:55.806-0300] {taskinstance.py:3503} INFO - 0 downstream tasks scheduled from follow-on schedule check
[2024-07-25T15:00:55.806-0300] {local_task_job_runner.py:222} INFO - ::endgroup::
