[2024-07-25T14:28:15.033-0300] {local_task_job_runner.py:120} INFO - ::group::Pre task execution logs
[2024-07-25T14:28:15.037-0300] {taskinstance.py:2076} INFO - Dependencies all met for dep_context=non-requeueable deps ti=<TaskInstance: Mercado_5m.get_5m_info scheduled__2024-07-25T13:20:00+00:00 [queued]>
[2024-07-25T14:28:15.040-0300] {taskinstance.py:2076} INFO - Dependencies all met for dep_context=requeueable deps ti=<TaskInstance: Mercado_5m.get_5m_info scheduled__2024-07-25T13:20:00+00:00 [queued]>
[2024-07-25T14:28:15.041-0300] {taskinstance.py:2306} INFO - Starting attempt 1 of 1
[2024-07-25T14:28:15.055-0300] {taskinstance.py:2330} INFO - Executing <Task(PythonOperator): get_5m_info> on 2024-07-25 13:20:00+00:00
[2024-07-25T14:28:15.057-0300] {standard_task_runner.py:64} INFO - Started process 2591036 to run task
[2024-07-25T14:28:15.059-0300] {standard_task_runner.py:90} INFO - Running: ['airflow', 'tasks', 'run', 'Mercado_5m', 'get_5m_info', 'scheduled__2024-07-25T13:20:00+00:00', '--job-id', '2114', '--raw', '--subdir', 'DAGS_FOLDER/mercado_dag.py', '--cfg-path', '/tmp/tmpd16f8fuy']
[2024-07-25T14:28:15.060-0300] {standard_task_runner.py:91} INFO - Job 2114: Subtask get_5m_info
[2024-07-25T14:28:15.084-0300] {task_command.py:426} INFO - Running <TaskInstance: Mercado_5m.get_5m_info scheduled__2024-07-25T13:20:00+00:00 [running]> on host Galaxybook.
[2024-07-25T14:28:15.132-0300] {taskinstance.py:2648} INFO - Exporting env vars: AIRFLOW_CTX_DAG_OWNER='airflow' AIRFLOW_CTX_DAG_ID='Mercado_5m' AIRFLOW_CTX_TASK_ID='get_5m_info' AIRFLOW_CTX_EXECUTION_DATE='2024-07-25T13:20:00+00:00' AIRFLOW_CTX_TRY_NUMBER='1' AIRFLOW_CTX_DAG_RUN_ID='scheduled__2024-07-25T13:20:00+00:00'
[2024-07-25T14:28:15.132-0300] {taskinstance.py:430} INFO - ::endgroup::
[2024-07-25T14:28:15.139-0300] {taskinstance.py:441} INFO - ::group::Post task execution logs
[2024-07-25T14:28:15.139-0300] {taskinstance.py:2905} ERROR - Task failed with exception
Traceback (most recent call last):
  File "/home/hugoviana/Documentos/data_pipeline_airflow/.venv/lib/python3.12/site-packages/airflow/models/taskinstance.py", line 465, in _execute_task
    result = _execute_callable(context=context, **execute_callable_kwargs)
             ^^^^^^^^^^^^^^^^^^^^^^^^^^^^^^^^^^^^^^^^^^^^^^^^^^^^^^^^^^^^^
  File "/home/hugoviana/Documentos/data_pipeline_airflow/.venv/lib/python3.12/site-packages/airflow/models/taskinstance.py", line 432, in _execute_callable
    return execute_callable(context=context, **execute_callable_kwargs)
           ^^^^^^^^^^^^^^^^^^^^^^^^^^^^^^^^^^^^^^^^^^^^^^^^^^^^^^^^^^^^
  File "/home/hugoviana/Documentos/data_pipeline_airflow/.venv/lib/python3.12/site-packages/airflow/models/baseoperator.py", line 401, in wrapper
    return func(self, *args, **kwargs)
           ^^^^^^^^^^^^^^^^^^^^^^^^^^^
  File "/home/hugoviana/Documentos/data_pipeline_airflow/.venv/lib/python3.12/site-packages/airflow/operators/python.py", line 232, in execute
    context_merge(context, self.op_kwargs, templates_dict=self.templates_dict)
  File "/home/hugoviana/Documentos/data_pipeline_airflow/.venv/lib/python3.12/site-packages/airflow/utils/context.py", line 266, in context_merge
    context.update(*args, **kwargs)
  File "<frozen _collections_abc>", line 987, in update
ValueError: too many values to unpack (expected 2)
[2024-07-25T14:28:15.143-0300] {taskinstance.py:1206} INFO - Marking task as FAILED. dag_id=Mercado_5m, task_id=get_5m_info, run_id=scheduled__2024-07-25T13:20:00+00:00, execution_date=20240725T132000, start_date=20240725T172815, end_date=20240725T172815
[2024-07-25T14:28:15.154-0300] {standard_task_runner.py:110} ERROR - Failed to execute job 2114 for task get_5m_info (too many values to unpack (expected 2); 2591036)
[2024-07-25T14:28:15.193-0300] {local_task_job_runner.py:243} INFO - Task exited with return code 1
[2024-07-25T14:28:15.199-0300] {taskinstance.py:3503} INFO - 0 downstream tasks scheduled from follow-on schedule check
[2024-07-25T14:28:15.199-0300] {local_task_job_runner.py:222} INFO - ::endgroup::
[2024-07-25T14:30:23.361-0300] {local_task_job_runner.py:120} INFO - ::group::Pre task execution logs
[2024-07-25T14:30:23.369-0300] {taskinstance.py:2076} INFO - Dependencies all met for dep_context=non-requeueable deps ti=<TaskInstance: Mercado_5m.get_5m_info scheduled__2024-07-25T13:20:00+00:00 [queued]>
[2024-07-25T14:30:23.372-0300] {taskinstance.py:2076} INFO - Dependencies all met for dep_context=requeueable deps ti=<TaskInstance: Mercado_5m.get_5m_info scheduled__2024-07-25T13:20:00+00:00 [queued]>
[2024-07-25T14:30:23.372-0300] {taskinstance.py:2306} INFO - Starting attempt 1 of 1
[2024-07-25T14:30:23.387-0300] {taskinstance.py:2330} INFO - Executing <Task(PythonOperator): get_5m_info> on 2024-07-25 13:20:00+00:00
[2024-07-25T14:30:23.389-0300] {standard_task_runner.py:64} INFO - Started process 2593230 to run task
[2024-07-25T14:30:23.391-0300] {standard_task_runner.py:90} INFO - Running: ['airflow', 'tasks', 'run', 'Mercado_5m', 'get_5m_info', 'scheduled__2024-07-25T13:20:00+00:00', '--job-id', '2098', '--raw', '--subdir', 'DAGS_FOLDER/mercado_dag.py', '--cfg-path', '/tmp/tmpucet7fwq']
[2024-07-25T14:30:23.392-0300] {standard_task_runner.py:91} INFO - Job 2098: Subtask get_5m_info
[2024-07-25T14:30:23.421-0300] {task_command.py:426} INFO - Running <TaskInstance: Mercado_5m.get_5m_info scheduled__2024-07-25T13:20:00+00:00 [running]> on host Galaxybook.
[2024-07-25T14:30:23.477-0300] {taskinstance.py:2648} INFO - Exporting env vars: AIRFLOW_CTX_DAG_OWNER='airflow' AIRFLOW_CTX_DAG_ID='Mercado_5m' AIRFLOW_CTX_TASK_ID='get_5m_info' AIRFLOW_CTX_EXECUTION_DATE='2024-07-25T13:20:00+00:00' AIRFLOW_CTX_TRY_NUMBER='1' AIRFLOW_CTX_DAG_RUN_ID='scheduled__2024-07-25T13:20:00+00:00'
[2024-07-25T14:30:23.478-0300] {taskinstance.py:430} INFO - ::endgroup::
[2024-07-25T14:30:23.486-0300] {taskinstance.py:441} INFO - ::group::Post task execution logs
[2024-07-25T14:30:23.486-0300] {taskinstance.py:2905} ERROR - Task failed with exception
Traceback (most recent call last):
  File "/home/hugoviana/Documentos/data_pipeline_airflow/.venv/lib/python3.12/site-packages/airflow/models/taskinstance.py", line 465, in _execute_task
    result = _execute_callable(context=context, **execute_callable_kwargs)
             ^^^^^^^^^^^^^^^^^^^^^^^^^^^^^^^^^^^^^^^^^^^^^^^^^^^^^^^^^^^^^
  File "/home/hugoviana/Documentos/data_pipeline_airflow/.venv/lib/python3.12/site-packages/airflow/models/taskinstance.py", line 432, in _execute_callable
    return execute_callable(context=context, **execute_callable_kwargs)
           ^^^^^^^^^^^^^^^^^^^^^^^^^^^^^^^^^^^^^^^^^^^^^^^^^^^^^^^^^^^^
  File "/home/hugoviana/Documentos/data_pipeline_airflow/.venv/lib/python3.12/site-packages/airflow/models/baseoperator.py", line 401, in wrapper
    return func(self, *args, **kwargs)
           ^^^^^^^^^^^^^^^^^^^^^^^^^^^
  File "/home/hugoviana/Documentos/data_pipeline_airflow/.venv/lib/python3.12/site-packages/airflow/operators/python.py", line 232, in execute
    context_merge(context, self.op_kwargs, templates_dict=self.templates_dict)
  File "/home/hugoviana/Documentos/data_pipeline_airflow/.venv/lib/python3.12/site-packages/airflow/utils/context.py", line 266, in context_merge
    context.update(*args, **kwargs)
  File "<frozen _collections_abc>", line 987, in update
ValueError: too many values to unpack (expected 2)
[2024-07-25T14:30:23.491-0300] {taskinstance.py:1206} INFO - Marking task as FAILED. dag_id=Mercado_5m, task_id=get_5m_info, run_id=scheduled__2024-07-25T13:20:00+00:00, execution_date=20240725T132000, start_date=20240725T173023, end_date=20240725T173023
[2024-07-25T14:30:23.502-0300] {standard_task_runner.py:110} ERROR - Failed to execute job 2098 for task get_5m_info (too many values to unpack (expected 2); 2593230)
[2024-07-25T14:30:23.524-0300] {local_task_job_runner.py:243} INFO - Task exited with return code 1
[2024-07-25T14:30:23.531-0300] {taskinstance.py:3503} INFO - 0 downstream tasks scheduled from follow-on schedule check
[2024-07-25T14:30:23.531-0300] {local_task_job_runner.py:222} INFO - ::endgroup::
[2024-07-25T15:00:32.021-0300] {local_task_job_runner.py:120} INFO - ::group::Pre task execution logs
[2024-07-25T15:00:32.027-0300] {taskinstance.py:2076} INFO - Dependencies all met for dep_context=non-requeueable deps ti=<TaskInstance: Mercado_5m.get_5m_info scheduled__2024-07-25T13:20:00+00:00 [queued]>
[2024-07-25T15:00:32.030-0300] {taskinstance.py:2076} INFO - Dependencies all met for dep_context=requeueable deps ti=<TaskInstance: Mercado_5m.get_5m_info scheduled__2024-07-25T13:20:00+00:00 [queued]>
[2024-07-25T15:00:32.030-0300] {taskinstance.py:2306} INFO - Starting attempt 1 of 1
[2024-07-25T15:00:32.044-0300] {taskinstance.py:2330} INFO - Executing <Task(PythonOperator): get_5m_info> on 2024-07-25 13:20:00+00:00
[2024-07-25T15:00:32.046-0300] {standard_task_runner.py:64} INFO - Started process 2619976 to run task
[2024-07-25T15:00:32.048-0300] {standard_task_runner.py:90} INFO - Running: ['airflow', 'tasks', 'run', 'Mercado_5m', 'get_5m_info', 'scheduled__2024-07-25T13:20:00+00:00', '--job-id', '2472', '--raw', '--subdir', 'DAGS_FOLDER/mercado_dag.py', '--cfg-path', '/tmp/tmpgi9ku2ii']
[2024-07-25T15:00:32.050-0300] {standard_task_runner.py:91} INFO - Job 2472: Subtask get_5m_info
[2024-07-25T15:00:32.078-0300] {task_command.py:426} INFO - Running <TaskInstance: Mercado_5m.get_5m_info scheduled__2024-07-25T13:20:00+00:00 [running]> on host Galaxybook.
[2024-07-25T15:00:32.132-0300] {taskinstance.py:2648} INFO - Exporting env vars: AIRFLOW_CTX_DAG_OWNER='airflow' AIRFLOW_CTX_DAG_ID='Mercado_5m' AIRFLOW_CTX_TASK_ID='get_5m_info' AIRFLOW_CTX_EXECUTION_DATE='2024-07-25T13:20:00+00:00' AIRFLOW_CTX_TRY_NUMBER='1' AIRFLOW_CTX_DAG_RUN_ID='scheduled__2024-07-25T13:20:00+00:00'
[2024-07-25T15:00:32.133-0300] {taskinstance.py:430} INFO - ::endgroup::
[2024-07-25T15:00:32.203-0300] {base.py:84} INFO - Using connection ID 'mercado_default' for task execution.
[2024-07-25T15:00:32.203-0300] {mercado_hook.py:31} INFO - URL: https://api.mercadobitcoin.net/api/v4/candles?symbol=BTC-BRL&resolution=5m&to=1721924700&from=1721924400
[2024-07-25T15:00:32.499-0300] {python.py:237} INFO - Done. Returned value was: None
[2024-07-25T15:00:32.499-0300] {taskinstance.py:441} INFO - ::group::Post task execution logs
[2024-07-25T15:00:32.502-0300] {taskinstance.py:1206} INFO - Marking task as SUCCESS. dag_id=Mercado_5m, task_id=get_5m_info, run_id=scheduled__2024-07-25T13:20:00+00:00, execution_date=20240725T132000, start_date=20240725T180032, end_date=20240725T180032
[2024-07-25T15:00:32.550-0300] {local_task_job_runner.py:243} INFO - Task exited with return code 0
[2024-07-25T15:00:32.557-0300] {taskinstance.py:3503} INFO - 0 downstream tasks scheduled from follow-on schedule check
[2024-07-25T15:00:32.557-0300] {local_task_job_runner.py:222} INFO - ::endgroup::
