[2024-07-25T14:28:51.980-0300] {local_task_job_runner.py:120} INFO - ::group::Pre task execution logs
[2024-07-25T14:28:51.985-0300] {taskinstance.py:2076} INFO - Dependencies all met for dep_context=non-requeueable deps ti=<TaskInstance: Mercado_5m.get_5m_info scheduled__2024-07-25T14:20:00+00:00 [queued]>
[2024-07-25T14:28:51.988-0300] {taskinstance.py:2076} INFO - Dependencies all met for dep_context=requeueable deps ti=<TaskInstance: Mercado_5m.get_5m_info scheduled__2024-07-25T14:20:00+00:00 [queued]>
[2024-07-25T14:28:51.988-0300] {taskinstance.py:2306} INFO - Starting attempt 1 of 1
[2024-07-25T14:28:52.004-0300] {taskinstance.py:2330} INFO - Executing <Task(PythonOperator): get_5m_info> on 2024-07-25 14:20:00+00:00
[2024-07-25T14:28:52.005-0300] {standard_task_runner.py:64} INFO - Started process 2591658 to run task
[2024-07-25T14:28:52.007-0300] {standard_task_runner.py:90} INFO - Running: ['airflow', 'tasks', 'run', 'Mercado_5m', 'get_5m_info', 'scheduled__2024-07-25T14:20:00+00:00', '--job-id', '2138', '--raw', '--subdir', 'DAGS_FOLDER/mercado_dag.py', '--cfg-path', '/tmp/tmpyf34xxtq']
[2024-07-25T14:28:52.008-0300] {standard_task_runner.py:91} INFO - Job 2138: Subtask get_5m_info
[2024-07-25T14:28:52.032-0300] {task_command.py:426} INFO - Running <TaskInstance: Mercado_5m.get_5m_info scheduled__2024-07-25T14:20:00+00:00 [running]> on host Galaxybook.
[2024-07-25T14:28:52.076-0300] {taskinstance.py:2648} INFO - Exporting env vars: AIRFLOW_CTX_DAG_OWNER='airflow' AIRFLOW_CTX_DAG_ID='Mercado_5m' AIRFLOW_CTX_TASK_ID='get_5m_info' AIRFLOW_CTX_EXECUTION_DATE='2024-07-25T14:20:00+00:00' AIRFLOW_CTX_TRY_NUMBER='1' AIRFLOW_CTX_DAG_RUN_ID='scheduled__2024-07-25T14:20:00+00:00'
[2024-07-25T14:28:52.076-0300] {taskinstance.py:430} INFO - ::endgroup::
[2024-07-25T14:28:52.083-0300] {taskinstance.py:441} INFO - ::group::Post task execution logs
[2024-07-25T14:28:52.083-0300] {taskinstance.py:2905} ERROR - Task failed with exception
Traceback (most recent call last):
  File "/home/hugoviana/Documentos/data_pipeline_airflow/.venv/lib/python3.12/site-packages/airflow/models/taskinstance.py", line 465, in _execute_task
    result = _execute_callable(context=context, **execute_callable_kwargs)
             ^^^^^^^^^^^^^^^^^^^^^^^^^^^^^^^^^^^^^^^^^^^^^^^^^^^^^^^^^^^^^
  File "/home/hugoviana/Documentos/data_pipeline_airflow/.venv/lib/python3.12/site-packages/airflow/models/taskinstance.py", line 432, in _execute_callable
    return execute_callable(context=context, **execute_callable_kwargs)
           ^^^^^^^^^^^^^^^^^^^^^^^^^^^^^^^^^^^^^^^^^^^^^^^^^^^^^^^^^^^^
  File "/home/hugoviana/Documentos/data_pipeline_airflow/.venv/lib/python3.12/site-packages/airflow/models/baseoperator.py", line 401, in wrapper
    return func(self, *args, **kwargs)
           ^^^^^^^^^^^^^^^^^^^^^^^^^^^
  File "/home/hugoviana/Documentos/data_pipeline_airflow/.venv/lib/python3.12/site-packages/airflow/operators/python.py", line 232, in execute
    context_merge(context, self.op_kwargs, templates_dict=self.templates_dict)
  File "/home/hugoviana/Documentos/data_pipeline_airflow/.venv/lib/python3.12/site-packages/airflow/utils/context.py", line 266, in context_merge
    context.update(*args, **kwargs)
  File "<frozen _collections_abc>", line 987, in update
ValueError: too many values to unpack (expected 2)
[2024-07-25T14:28:52.087-0300] {taskinstance.py:1206} INFO - Marking task as FAILED. dag_id=Mercado_5m, task_id=get_5m_info, run_id=scheduled__2024-07-25T14:20:00+00:00, execution_date=20240725T142000, start_date=20240725T172851, end_date=20240725T172852
[2024-07-25T14:28:52.096-0300] {standard_task_runner.py:110} ERROR - Failed to execute job 2138 for task get_5m_info (too many values to unpack (expected 2); 2591658)
[2024-07-25T14:28:52.100-0300] {local_task_job_runner.py:243} INFO - Task exited with return code 1
[2024-07-25T14:28:52.105-0300] {taskinstance.py:3503} INFO - 0 downstream tasks scheduled from follow-on schedule check
[2024-07-25T14:28:52.105-0300] {local_task_job_runner.py:222} INFO - ::endgroup::
[2024-07-25T14:30:45.146-0300] {local_task_job_runner.py:120} INFO - ::group::Pre task execution logs
[2024-07-25T14:30:45.152-0300] {taskinstance.py:2076} INFO - Dependencies all met for dep_context=non-requeueable deps ti=<TaskInstance: Mercado_5m.get_5m_info scheduled__2024-07-25T14:20:00+00:00 [queued]>
[2024-07-25T14:30:45.156-0300] {taskinstance.py:2076} INFO - Dependencies all met for dep_context=requeueable deps ti=<TaskInstance: Mercado_5m.get_5m_info scheduled__2024-07-25T14:20:00+00:00 [queued]>
[2024-07-25T14:30:45.156-0300] {taskinstance.py:2306} INFO - Starting attempt 1 of 1
[2024-07-25T14:30:45.171-0300] {taskinstance.py:2330} INFO - Executing <Task(PythonOperator): get_5m_info> on 2024-07-25 14:20:00+00:00
[2024-07-25T14:30:45.173-0300] {standard_task_runner.py:64} INFO - Started process 2593580 to run task
[2024-07-25T14:30:45.176-0300] {standard_task_runner.py:90} INFO - Running: ['airflow', 'tasks', 'run', 'Mercado_5m', 'get_5m_info', 'scheduled__2024-07-25T14:20:00+00:00', '--job-id', '2110', '--raw', '--subdir', 'DAGS_FOLDER/mercado_dag.py', '--cfg-path', '/tmp/tmpsyspxwzu']
[2024-07-25T14:30:45.176-0300] {standard_task_runner.py:91} INFO - Job 2110: Subtask get_5m_info
[2024-07-25T14:30:45.203-0300] {task_command.py:426} INFO - Running <TaskInstance: Mercado_5m.get_5m_info scheduled__2024-07-25T14:20:00+00:00 [running]> on host Galaxybook.
[2024-07-25T14:30:45.252-0300] {taskinstance.py:2648} INFO - Exporting env vars: AIRFLOW_CTX_DAG_OWNER='airflow' AIRFLOW_CTX_DAG_ID='Mercado_5m' AIRFLOW_CTX_TASK_ID='get_5m_info' AIRFLOW_CTX_EXECUTION_DATE='2024-07-25T14:20:00+00:00' AIRFLOW_CTX_TRY_NUMBER='1' AIRFLOW_CTX_DAG_RUN_ID='scheduled__2024-07-25T14:20:00+00:00'
[2024-07-25T14:30:45.253-0300] {taskinstance.py:430} INFO - ::endgroup::
[2024-07-25T14:30:45.259-0300] {taskinstance.py:441} INFO - ::group::Post task execution logs
[2024-07-25T14:30:45.259-0300] {taskinstance.py:2905} ERROR - Task failed with exception
Traceback (most recent call last):
  File "/home/hugoviana/Documentos/data_pipeline_airflow/.venv/lib/python3.12/site-packages/airflow/models/taskinstance.py", line 465, in _execute_task
    result = _execute_callable(context=context, **execute_callable_kwargs)
             ^^^^^^^^^^^^^^^^^^^^^^^^^^^^^^^^^^^^^^^^^^^^^^^^^^^^^^^^^^^^^
  File "/home/hugoviana/Documentos/data_pipeline_airflow/.venv/lib/python3.12/site-packages/airflow/models/taskinstance.py", line 432, in _execute_callable
    return execute_callable(context=context, **execute_callable_kwargs)
           ^^^^^^^^^^^^^^^^^^^^^^^^^^^^^^^^^^^^^^^^^^^^^^^^^^^^^^^^^^^^
  File "/home/hugoviana/Documentos/data_pipeline_airflow/.venv/lib/python3.12/site-packages/airflow/models/baseoperator.py", line 401, in wrapper
    return func(self, *args, **kwargs)
           ^^^^^^^^^^^^^^^^^^^^^^^^^^^
  File "/home/hugoviana/Documentos/data_pipeline_airflow/.venv/lib/python3.12/site-packages/airflow/operators/python.py", line 232, in execute
    context_merge(context, self.op_kwargs, templates_dict=self.templates_dict)
  File "/home/hugoviana/Documentos/data_pipeline_airflow/.venv/lib/python3.12/site-packages/airflow/utils/context.py", line 266, in context_merge
    context.update(*args, **kwargs)
  File "<frozen _collections_abc>", line 987, in update
ValueError: too many values to unpack (expected 2)
[2024-07-25T14:30:45.263-0300] {taskinstance.py:1206} INFO - Marking task as FAILED. dag_id=Mercado_5m, task_id=get_5m_info, run_id=scheduled__2024-07-25T14:20:00+00:00, execution_date=20240725T142000, start_date=20240725T173045, end_date=20240725T173045
[2024-07-25T14:30:45.274-0300] {standard_task_runner.py:110} ERROR - Failed to execute job 2110 for task get_5m_info (too many values to unpack (expected 2); 2593580)
[2024-07-25T14:30:45.310-0300] {local_task_job_runner.py:243} INFO - Task exited with return code 1
[2024-07-25T14:30:45.318-0300] {taskinstance.py:3503} INFO - 0 downstream tasks scheduled from follow-on schedule check
[2024-07-25T14:30:45.318-0300] {local_task_job_runner.py:222} INFO - ::endgroup::
[2024-07-25T15:01:01.124-0300] {local_task_job_runner.py:120} INFO - ::group::Pre task execution logs
[2024-07-25T15:01:01.131-0300] {taskinstance.py:2076} INFO - Dependencies all met for dep_context=non-requeueable deps ti=<TaskInstance: Mercado_5m.get_5m_info scheduled__2024-07-25T14:20:00+00:00 [queued]>
[2024-07-25T15:01:01.134-0300] {taskinstance.py:2076} INFO - Dependencies all met for dep_context=requeueable deps ti=<TaskInstance: Mercado_5m.get_5m_info scheduled__2024-07-25T14:20:00+00:00 [queued]>
[2024-07-25T15:01:01.134-0300] {taskinstance.py:2306} INFO - Starting attempt 1 of 1
[2024-07-25T15:01:01.147-0300] {taskinstance.py:2330} INFO - Executing <Task(PythonOperator): get_5m_info> on 2024-07-25 14:20:00+00:00
[2024-07-25T15:01:01.148-0300] {standard_task_runner.py:64} INFO - Started process 2620463 to run task
[2024-07-25T15:01:01.151-0300] {standard_task_runner.py:90} INFO - Running: ['airflow', 'tasks', 'run', 'Mercado_5m', 'get_5m_info', 'scheduled__2024-07-25T14:20:00+00:00', '--job-id', '2484', '--raw', '--subdir', 'DAGS_FOLDER/mercado_dag.py', '--cfg-path', '/tmp/tmp_655ez7p']
[2024-07-25T15:01:01.152-0300] {standard_task_runner.py:91} INFO - Job 2484: Subtask get_5m_info
[2024-07-25T15:01:01.179-0300] {task_command.py:426} INFO - Running <TaskInstance: Mercado_5m.get_5m_info scheduled__2024-07-25T14:20:00+00:00 [running]> on host Galaxybook.
[2024-07-25T15:01:01.231-0300] {taskinstance.py:2648} INFO - Exporting env vars: AIRFLOW_CTX_DAG_OWNER='airflow' AIRFLOW_CTX_DAG_ID='Mercado_5m' AIRFLOW_CTX_TASK_ID='get_5m_info' AIRFLOW_CTX_EXECUTION_DATE='2024-07-25T14:20:00+00:00' AIRFLOW_CTX_TRY_NUMBER='1' AIRFLOW_CTX_DAG_RUN_ID='scheduled__2024-07-25T14:20:00+00:00'
[2024-07-25T15:01:01.232-0300] {taskinstance.py:430} INFO - ::endgroup::
[2024-07-25T15:01:01.293-0300] {base.py:84} INFO - Using connection ID 'mercado_default' for task execution.
[2024-07-25T15:01:01.293-0300] {mercado_hook.py:31} INFO - URL: https://api.mercadobitcoin.net/api/v4/candles?symbol=BTC-BRL&resolution=5m&to=1721928300&from=1721928000
[2024-07-25T15:01:01.576-0300] {python.py:237} INFO - Done. Returned value was: None
[2024-07-25T15:01:01.577-0300] {taskinstance.py:441} INFO - ::group::Post task execution logs
[2024-07-25T15:01:01.580-0300] {taskinstance.py:1206} INFO - Marking task as SUCCESS. dag_id=Mercado_5m, task_id=get_5m_info, run_id=scheduled__2024-07-25T14:20:00+00:00, execution_date=20240725T142000, start_date=20240725T180101, end_date=20240725T180101
[2024-07-25T15:01:01.610-0300] {local_task_job_runner.py:243} INFO - Task exited with return code 0
[2024-07-25T15:01:01.617-0300] {taskinstance.py:3503} INFO - 0 downstream tasks scheduled from follow-on schedule check
[2024-07-25T15:01:01.617-0300] {local_task_job_runner.py:222} INFO - ::endgroup::
