[2024-07-25T14:28:44.388-0300] {local_task_job_runner.py:120} INFO - ::group::Pre task execution logs
[2024-07-25T14:28:44.393-0300] {taskinstance.py:2076} INFO - Dependencies all met for dep_context=non-requeueable deps ti=<TaskInstance: Mercado_5m.get_5m_info scheduled__2024-07-25T14:10:00+00:00 [queued]>
[2024-07-25T14:28:44.396-0300] {taskinstance.py:2076} INFO - Dependencies all met for dep_context=requeueable deps ti=<TaskInstance: Mercado_5m.get_5m_info scheduled__2024-07-25T14:10:00+00:00 [queued]>
[2024-07-25T14:28:44.396-0300] {taskinstance.py:2306} INFO - Starting attempt 1 of 1
[2024-07-25T14:28:44.410-0300] {taskinstance.py:2330} INFO - Executing <Task(PythonOperator): get_5m_info> on 2024-07-25 14:10:00+00:00
[2024-07-25T14:28:44.412-0300] {standard_task_runner.py:64} INFO - Started process 2591534 to run task
[2024-07-25T14:28:44.413-0300] {standard_task_runner.py:90} INFO - Running: ['airflow', 'tasks', 'run', 'Mercado_5m', 'get_5m_info', 'scheduled__2024-07-25T14:10:00+00:00', '--job-id', '2134', '--raw', '--subdir', 'DAGS_FOLDER/mercado_dag.py', '--cfg-path', '/tmp/tmplfusl7gu']
[2024-07-25T14:28:44.414-0300] {standard_task_runner.py:91} INFO - Job 2134: Subtask get_5m_info
[2024-07-25T14:28:44.441-0300] {task_command.py:426} INFO - Running <TaskInstance: Mercado_5m.get_5m_info scheduled__2024-07-25T14:10:00+00:00 [running]> on host Galaxybook.
[2024-07-25T14:28:44.487-0300] {taskinstance.py:2648} INFO - Exporting env vars: AIRFLOW_CTX_DAG_OWNER='airflow' AIRFLOW_CTX_DAG_ID='Mercado_5m' AIRFLOW_CTX_TASK_ID='get_5m_info' AIRFLOW_CTX_EXECUTION_DATE='2024-07-25T14:10:00+00:00' AIRFLOW_CTX_TRY_NUMBER='1' AIRFLOW_CTX_DAG_RUN_ID='scheduled__2024-07-25T14:10:00+00:00'
[2024-07-25T14:28:44.487-0300] {taskinstance.py:430} INFO - ::endgroup::
[2024-07-25T14:28:44.494-0300] {taskinstance.py:441} INFO - ::group::Post task execution logs
[2024-07-25T14:28:44.494-0300] {taskinstance.py:2905} ERROR - Task failed with exception
Traceback (most recent call last):
  File "/home/hugoviana/Documentos/data_pipeline_airflow/.venv/lib/python3.12/site-packages/airflow/models/taskinstance.py", line 465, in _execute_task
    result = _execute_callable(context=context, **execute_callable_kwargs)
             ^^^^^^^^^^^^^^^^^^^^^^^^^^^^^^^^^^^^^^^^^^^^^^^^^^^^^^^^^^^^^
  File "/home/hugoviana/Documentos/data_pipeline_airflow/.venv/lib/python3.12/site-packages/airflow/models/taskinstance.py", line 432, in _execute_callable
    return execute_callable(context=context, **execute_callable_kwargs)
           ^^^^^^^^^^^^^^^^^^^^^^^^^^^^^^^^^^^^^^^^^^^^^^^^^^^^^^^^^^^^
  File "/home/hugoviana/Documentos/data_pipeline_airflow/.venv/lib/python3.12/site-packages/airflow/models/baseoperator.py", line 401, in wrapper
    return func(self, *args, **kwargs)
           ^^^^^^^^^^^^^^^^^^^^^^^^^^^
  File "/home/hugoviana/Documentos/data_pipeline_airflow/.venv/lib/python3.12/site-packages/airflow/operators/python.py", line 232, in execute
    context_merge(context, self.op_kwargs, templates_dict=self.templates_dict)
  File "/home/hugoviana/Documentos/data_pipeline_airflow/.venv/lib/python3.12/site-packages/airflow/utils/context.py", line 266, in context_merge
    context.update(*args, **kwargs)
  File "<frozen _collections_abc>", line 987, in update
ValueError: too many values to unpack (expected 2)
[2024-07-25T14:28:44.498-0300] {taskinstance.py:1206} INFO - Marking task as FAILED. dag_id=Mercado_5m, task_id=get_5m_info, run_id=scheduled__2024-07-25T14:10:00+00:00, execution_date=20240725T141000, start_date=20240725T172844, end_date=20240725T172844
[2024-07-25T14:28:44.509-0300] {standard_task_runner.py:110} ERROR - Failed to execute job 2134 for task get_5m_info (too many values to unpack (expected 2); 2591534)
[2024-07-25T14:28:44.547-0300] {local_task_job_runner.py:243} INFO - Task exited with return code 1
[2024-07-25T14:28:44.555-0300] {taskinstance.py:3503} INFO - 0 downstream tasks scheduled from follow-on schedule check
[2024-07-25T14:28:44.555-0300] {local_task_job_runner.py:222} INFO - ::endgroup::
[2024-07-25T14:30:41.375-0300] {local_task_job_runner.py:120} INFO - ::group::Pre task execution logs
[2024-07-25T14:30:41.383-0300] {taskinstance.py:2076} INFO - Dependencies all met for dep_context=non-requeueable deps ti=<TaskInstance: Mercado_5m.get_5m_info scheduled__2024-07-25T14:10:00+00:00 [queued]>
[2024-07-25T14:30:41.386-0300] {taskinstance.py:2076} INFO - Dependencies all met for dep_context=requeueable deps ti=<TaskInstance: Mercado_5m.get_5m_info scheduled__2024-07-25T14:10:00+00:00 [queued]>
[2024-07-25T14:30:41.387-0300] {taskinstance.py:2306} INFO - Starting attempt 1 of 1
[2024-07-25T14:30:41.399-0300] {taskinstance.py:2330} INFO - Executing <Task(PythonOperator): get_5m_info> on 2024-07-25 14:10:00+00:00
[2024-07-25T14:30:41.401-0300] {standard_task_runner.py:64} INFO - Started process 2593537 to run task
[2024-07-25T14:30:41.404-0300] {standard_task_runner.py:90} INFO - Running: ['airflow', 'tasks', 'run', 'Mercado_5m', 'get_5m_info', 'scheduled__2024-07-25T14:10:00+00:00', '--job-id', '2108', '--raw', '--subdir', 'DAGS_FOLDER/mercado_dag.py', '--cfg-path', '/tmp/tmpnddnrv1h']
[2024-07-25T14:30:41.406-0300] {standard_task_runner.py:91} INFO - Job 2108: Subtask get_5m_info
[2024-07-25T14:30:41.442-0300] {task_command.py:426} INFO - Running <TaskInstance: Mercado_5m.get_5m_info scheduled__2024-07-25T14:10:00+00:00 [running]> on host Galaxybook.
[2024-07-25T14:30:41.491-0300] {taskinstance.py:2648} INFO - Exporting env vars: AIRFLOW_CTX_DAG_OWNER='airflow' AIRFLOW_CTX_DAG_ID='Mercado_5m' AIRFLOW_CTX_TASK_ID='get_5m_info' AIRFLOW_CTX_EXECUTION_DATE='2024-07-25T14:10:00+00:00' AIRFLOW_CTX_TRY_NUMBER='1' AIRFLOW_CTX_DAG_RUN_ID='scheduled__2024-07-25T14:10:00+00:00'
[2024-07-25T14:30:41.492-0300] {taskinstance.py:430} INFO - ::endgroup::
[2024-07-25T14:30:41.499-0300] {taskinstance.py:441} INFO - ::group::Post task execution logs
[2024-07-25T14:30:41.499-0300] {taskinstance.py:2905} ERROR - Task failed with exception
Traceback (most recent call last):
  File "/home/hugoviana/Documentos/data_pipeline_airflow/.venv/lib/python3.12/site-packages/airflow/models/taskinstance.py", line 465, in _execute_task
    result = _execute_callable(context=context, **execute_callable_kwargs)
             ^^^^^^^^^^^^^^^^^^^^^^^^^^^^^^^^^^^^^^^^^^^^^^^^^^^^^^^^^^^^^
  File "/home/hugoviana/Documentos/data_pipeline_airflow/.venv/lib/python3.12/site-packages/airflow/models/taskinstance.py", line 432, in _execute_callable
    return execute_callable(context=context, **execute_callable_kwargs)
           ^^^^^^^^^^^^^^^^^^^^^^^^^^^^^^^^^^^^^^^^^^^^^^^^^^^^^^^^^^^^
  File "/home/hugoviana/Documentos/data_pipeline_airflow/.venv/lib/python3.12/site-packages/airflow/models/baseoperator.py", line 401, in wrapper
    return func(self, *args, **kwargs)
           ^^^^^^^^^^^^^^^^^^^^^^^^^^^
  File "/home/hugoviana/Documentos/data_pipeline_airflow/.venv/lib/python3.12/site-packages/airflow/operators/python.py", line 232, in execute
    context_merge(context, self.op_kwargs, templates_dict=self.templates_dict)
  File "/home/hugoviana/Documentos/data_pipeline_airflow/.venv/lib/python3.12/site-packages/airflow/utils/context.py", line 266, in context_merge
    context.update(*args, **kwargs)
  File "<frozen _collections_abc>", line 987, in update
ValueError: too many values to unpack (expected 2)
[2024-07-25T14:30:41.503-0300] {taskinstance.py:1206} INFO - Marking task as FAILED. dag_id=Mercado_5m, task_id=get_5m_info, run_id=scheduled__2024-07-25T14:10:00+00:00, execution_date=20240725T141000, start_date=20240725T173041, end_date=20240725T173041
[2024-07-25T14:30:41.513-0300] {standard_task_runner.py:110} ERROR - Failed to execute job 2108 for task get_5m_info (too many values to unpack (expected 2); 2593537)
[2024-07-25T14:30:41.539-0300] {local_task_job_runner.py:243} INFO - Task exited with return code 1
[2024-07-25T14:30:41.547-0300] {taskinstance.py:3503} INFO - 0 downstream tasks scheduled from follow-on schedule check
[2024-07-25T14:30:41.547-0300] {local_task_job_runner.py:222} INFO - ::endgroup::
[2024-07-25T15:00:57.892-0300] {local_task_job_runner.py:120} INFO - ::group::Pre task execution logs
[2024-07-25T15:00:57.897-0300] {taskinstance.py:2076} INFO - Dependencies all met for dep_context=non-requeueable deps ti=<TaskInstance: Mercado_5m.get_5m_info scheduled__2024-07-25T14:10:00+00:00 [queued]>
[2024-07-25T15:00:57.901-0300] {taskinstance.py:2076} INFO - Dependencies all met for dep_context=requeueable deps ti=<TaskInstance: Mercado_5m.get_5m_info scheduled__2024-07-25T14:10:00+00:00 [queued]>
[2024-07-25T15:00:57.902-0300] {taskinstance.py:2306} INFO - Starting attempt 1 of 1
[2024-07-25T15:00:57.917-0300] {taskinstance.py:2330} INFO - Executing <Task(PythonOperator): get_5m_info> on 2024-07-25 14:10:00+00:00
[2024-07-25T15:00:57.919-0300] {standard_task_runner.py:64} INFO - Started process 2620385 to run task
[2024-07-25T15:00:57.921-0300] {standard_task_runner.py:90} INFO - Running: ['airflow', 'tasks', 'run', 'Mercado_5m', 'get_5m_info', 'scheduled__2024-07-25T14:10:00+00:00', '--job-id', '2482', '--raw', '--subdir', 'DAGS_FOLDER/mercado_dag.py', '--cfg-path', '/tmp/tmp6qgcxl7e']
[2024-07-25T15:00:57.922-0300] {standard_task_runner.py:91} INFO - Job 2482: Subtask get_5m_info
[2024-07-25T15:00:57.949-0300] {task_command.py:426} INFO - Running <TaskInstance: Mercado_5m.get_5m_info scheduled__2024-07-25T14:10:00+00:00 [running]> on host Galaxybook.
[2024-07-25T15:00:58.001-0300] {taskinstance.py:2648} INFO - Exporting env vars: AIRFLOW_CTX_DAG_OWNER='airflow' AIRFLOW_CTX_DAG_ID='Mercado_5m' AIRFLOW_CTX_TASK_ID='get_5m_info' AIRFLOW_CTX_EXECUTION_DATE='2024-07-25T14:10:00+00:00' AIRFLOW_CTX_TRY_NUMBER='1' AIRFLOW_CTX_DAG_RUN_ID='scheduled__2024-07-25T14:10:00+00:00'
[2024-07-25T15:00:58.002-0300] {taskinstance.py:430} INFO - ::endgroup::
[2024-07-25T15:00:58.063-0300] {base.py:84} INFO - Using connection ID 'mercado_default' for task execution.
[2024-07-25T15:00:58.063-0300] {mercado_hook.py:31} INFO - URL: https://api.mercadobitcoin.net/api/v4/candles?symbol=BTC-BRL&resolution=5m&to=1721927700&from=1721927400
[2024-07-25T15:00:58.344-0300] {python.py:237} INFO - Done. Returned value was: None
[2024-07-25T15:00:58.345-0300] {taskinstance.py:441} INFO - ::group::Post task execution logs
[2024-07-25T15:00:58.348-0300] {taskinstance.py:1206} INFO - Marking task as SUCCESS. dag_id=Mercado_5m, task_id=get_5m_info, run_id=scheduled__2024-07-25T14:10:00+00:00, execution_date=20240725T141000, start_date=20240725T180057, end_date=20240725T180058
[2024-07-25T15:00:58.384-0300] {local_task_job_runner.py:243} INFO - Task exited with return code 0
[2024-07-25T15:00:58.399-0300] {taskinstance.py:3503} INFO - 0 downstream tasks scheduled from follow-on schedule check
[2024-07-25T15:00:58.399-0300] {local_task_job_runner.py:222} INFO - ::endgroup::
