[2024-07-25T14:27:49.503-0300] {local_task_job_runner.py:120} INFO - ::group::Pre task execution logs
[2024-07-25T14:27:49.508-0300] {taskinstance.py:2076} INFO - Dependencies all met for dep_context=non-requeueable deps ti=<TaskInstance: Mercado_5m.get_5m_info scheduled__2024-07-25T12:40:00+00:00 [queued]>
[2024-07-25T14:27:49.511-0300] {taskinstance.py:2076} INFO - Dependencies all met for dep_context=requeueable deps ti=<TaskInstance: Mercado_5m.get_5m_info scheduled__2024-07-25T12:40:00+00:00 [queued]>
[2024-07-25T14:27:49.511-0300] {taskinstance.py:2306} INFO - Starting attempt 1 of 1
[2024-07-25T14:27:49.523-0300] {taskinstance.py:2330} INFO - Executing <Task(PythonOperator): get_5m_info> on 2024-07-25 12:40:00+00:00
[2024-07-25T14:27:49.525-0300] {standard_task_runner.py:64} INFO - Started process 2590610 to run task
[2024-07-25T14:27:49.527-0300] {standard_task_runner.py:90} INFO - Running: ['airflow', 'tasks', 'run', 'Mercado_5m', 'get_5m_info', 'scheduled__2024-07-25T12:40:00+00:00', '--job-id', '2098', '--raw', '--subdir', 'DAGS_FOLDER/mercado_dag.py', '--cfg-path', '/tmp/tmpza93ptim']
[2024-07-25T14:27:49.528-0300] {standard_task_runner.py:91} INFO - Job 2098: Subtask get_5m_info
[2024-07-25T14:27:49.557-0300] {task_command.py:426} INFO - Running <TaskInstance: Mercado_5m.get_5m_info scheduled__2024-07-25T12:40:00+00:00 [running]> on host Galaxybook.
[2024-07-25T14:27:49.606-0300] {taskinstance.py:2648} INFO - Exporting env vars: AIRFLOW_CTX_DAG_OWNER='airflow' AIRFLOW_CTX_DAG_ID='Mercado_5m' AIRFLOW_CTX_TASK_ID='get_5m_info' AIRFLOW_CTX_EXECUTION_DATE='2024-07-25T12:40:00+00:00' AIRFLOW_CTX_TRY_NUMBER='1' AIRFLOW_CTX_DAG_RUN_ID='scheduled__2024-07-25T12:40:00+00:00'
[2024-07-25T14:27:49.607-0300] {taskinstance.py:430} INFO - ::endgroup::
[2024-07-25T14:27:49.615-0300] {taskinstance.py:441} INFO - ::group::Post task execution logs
[2024-07-25T14:27:49.615-0300] {taskinstance.py:2905} ERROR - Task failed with exception
Traceback (most recent call last):
  File "/home/hugoviana/Documentos/data_pipeline_airflow/.venv/lib/python3.12/site-packages/airflow/models/taskinstance.py", line 465, in _execute_task
    result = _execute_callable(context=context, **execute_callable_kwargs)
             ^^^^^^^^^^^^^^^^^^^^^^^^^^^^^^^^^^^^^^^^^^^^^^^^^^^^^^^^^^^^^
  File "/home/hugoviana/Documentos/data_pipeline_airflow/.venv/lib/python3.12/site-packages/airflow/models/taskinstance.py", line 432, in _execute_callable
    return execute_callable(context=context, **execute_callable_kwargs)
           ^^^^^^^^^^^^^^^^^^^^^^^^^^^^^^^^^^^^^^^^^^^^^^^^^^^^^^^^^^^^
  File "/home/hugoviana/Documentos/data_pipeline_airflow/.venv/lib/python3.12/site-packages/airflow/models/baseoperator.py", line 401, in wrapper
    return func(self, *args, **kwargs)
           ^^^^^^^^^^^^^^^^^^^^^^^^^^^
  File "/home/hugoviana/Documentos/data_pipeline_airflow/.venv/lib/python3.12/site-packages/airflow/operators/python.py", line 232, in execute
    context_merge(context, self.op_kwargs, templates_dict=self.templates_dict)
  File "/home/hugoviana/Documentos/data_pipeline_airflow/.venv/lib/python3.12/site-packages/airflow/utils/context.py", line 266, in context_merge
    context.update(*args, **kwargs)
  File "<frozen _collections_abc>", line 987, in update
ValueError: too many values to unpack (expected 2)
[2024-07-25T14:27:49.617-0300] {taskinstance.py:1206} INFO - Marking task as FAILED. dag_id=Mercado_5m, task_id=get_5m_info, run_id=scheduled__2024-07-25T12:40:00+00:00, execution_date=20240725T124000, start_date=20240725T172749, end_date=20240725T172749
[2024-07-25T14:27:49.691-0300] {standard_task_runner.py:110} ERROR - Failed to execute job 2098 for task get_5m_info (too many values to unpack (expected 2); 2590610)
[2024-07-25T14:27:49.700-0300] {local_task_job_runner.py:243} INFO - Task exited with return code 1
[2024-07-25T14:27:49.707-0300] {taskinstance.py:3503} INFO - 0 downstream tasks scheduled from follow-on schedule check
[2024-07-25T14:27:49.707-0300] {local_task_job_runner.py:222} INFO - ::endgroup::
[2024-07-25T14:30:11.180-0300] {local_task_job_runner.py:120} INFO - ::group::Pre task execution logs
[2024-07-25T14:30:11.186-0300] {taskinstance.py:2076} INFO - Dependencies all met for dep_context=non-requeueable deps ti=<TaskInstance: Mercado_5m.get_5m_info scheduled__2024-07-25T12:40:00+00:00 [queued]>
[2024-07-25T14:30:11.189-0300] {taskinstance.py:2076} INFO - Dependencies all met for dep_context=requeueable deps ti=<TaskInstance: Mercado_5m.get_5m_info scheduled__2024-07-25T12:40:00+00:00 [queued]>
[2024-07-25T14:30:11.189-0300] {taskinstance.py:2306} INFO - Starting attempt 1 of 1
[2024-07-25T14:30:11.202-0300] {taskinstance.py:2330} INFO - Executing <Task(PythonOperator): get_5m_info> on 2024-07-25 12:40:00+00:00
[2024-07-25T14:30:11.203-0300] {standard_task_runner.py:64} INFO - Started process 2593014 to run task
[2024-07-25T14:30:11.205-0300] {standard_task_runner.py:90} INFO - Running: ['airflow', 'tasks', 'run', 'Mercado_5m', 'get_5m_info', 'scheduled__2024-07-25T12:40:00+00:00', '--job-id', '2090', '--raw', '--subdir', 'DAGS_FOLDER/mercado_dag.py', '--cfg-path', '/tmp/tmpjc3aend3']
[2024-07-25T14:30:11.206-0300] {standard_task_runner.py:91} INFO - Job 2090: Subtask get_5m_info
[2024-07-25T14:30:11.232-0300] {task_command.py:426} INFO - Running <TaskInstance: Mercado_5m.get_5m_info scheduled__2024-07-25T12:40:00+00:00 [running]> on host Galaxybook.
[2024-07-25T14:30:11.287-0300] {taskinstance.py:2648} INFO - Exporting env vars: AIRFLOW_CTX_DAG_OWNER='airflow' AIRFLOW_CTX_DAG_ID='Mercado_5m' AIRFLOW_CTX_TASK_ID='get_5m_info' AIRFLOW_CTX_EXECUTION_DATE='2024-07-25T12:40:00+00:00' AIRFLOW_CTX_TRY_NUMBER='1' AIRFLOW_CTX_DAG_RUN_ID='scheduled__2024-07-25T12:40:00+00:00'
[2024-07-25T14:30:11.287-0300] {taskinstance.py:430} INFO - ::endgroup::
[2024-07-25T14:30:11.294-0300] {taskinstance.py:441} INFO - ::group::Post task execution logs
[2024-07-25T14:30:11.294-0300] {taskinstance.py:2905} ERROR - Task failed with exception
Traceback (most recent call last):
  File "/home/hugoviana/Documentos/data_pipeline_airflow/.venv/lib/python3.12/site-packages/airflow/models/taskinstance.py", line 465, in _execute_task
    result = _execute_callable(context=context, **execute_callable_kwargs)
             ^^^^^^^^^^^^^^^^^^^^^^^^^^^^^^^^^^^^^^^^^^^^^^^^^^^^^^^^^^^^^
  File "/home/hugoviana/Documentos/data_pipeline_airflow/.venv/lib/python3.12/site-packages/airflow/models/taskinstance.py", line 432, in _execute_callable
    return execute_callable(context=context, **execute_callable_kwargs)
           ^^^^^^^^^^^^^^^^^^^^^^^^^^^^^^^^^^^^^^^^^^^^^^^^^^^^^^^^^^^^
  File "/home/hugoviana/Documentos/data_pipeline_airflow/.venv/lib/python3.12/site-packages/airflow/models/baseoperator.py", line 401, in wrapper
    return func(self, *args, **kwargs)
           ^^^^^^^^^^^^^^^^^^^^^^^^^^^
  File "/home/hugoviana/Documentos/data_pipeline_airflow/.venv/lib/python3.12/site-packages/airflow/operators/python.py", line 232, in execute
    context_merge(context, self.op_kwargs, templates_dict=self.templates_dict)
  File "/home/hugoviana/Documentos/data_pipeline_airflow/.venv/lib/python3.12/site-packages/airflow/utils/context.py", line 266, in context_merge
    context.update(*args, **kwargs)
  File "<frozen _collections_abc>", line 987, in update
ValueError: too many values to unpack (expected 2)
[2024-07-25T14:30:11.297-0300] {taskinstance.py:1206} INFO - Marking task as FAILED. dag_id=Mercado_5m, task_id=get_5m_info, run_id=scheduled__2024-07-25T12:40:00+00:00, execution_date=20240725T124000, start_date=20240725T173011, end_date=20240725T173011
[2024-07-25T14:30:11.309-0300] {standard_task_runner.py:110} ERROR - Failed to execute job 2090 for task get_5m_info (too many values to unpack (expected 2); 2593014)
[2024-07-25T14:30:11.339-0300] {local_task_job_runner.py:243} INFO - Task exited with return code 1
[2024-07-25T14:30:11.345-0300] {taskinstance.py:3503} INFO - 0 downstream tasks scheduled from follow-on schedule check
[2024-07-25T14:30:11.346-0300] {local_task_job_runner.py:222} INFO - ::endgroup::
[2024-07-25T15:00:12.884-0300] {local_task_job_runner.py:120} INFO - ::group::Pre task execution logs
[2024-07-25T15:00:12.896-0300] {taskinstance.py:2076} INFO - Dependencies all met for dep_context=non-requeueable deps ti=<TaskInstance: Mercado_5m.get_5m_info scheduled__2024-07-25T12:40:00+00:00 [queued]>
[2024-07-25T15:00:12.900-0300] {taskinstance.py:2076} INFO - Dependencies all met for dep_context=requeueable deps ti=<TaskInstance: Mercado_5m.get_5m_info scheduled__2024-07-25T12:40:00+00:00 [queued]>
[2024-07-25T15:00:12.900-0300] {taskinstance.py:2306} INFO - Starting attempt 1 of 1
[2024-07-25T15:00:12.914-0300] {taskinstance.py:2330} INFO - Executing <Task(PythonOperator): get_5m_info> on 2024-07-25 12:40:00+00:00
[2024-07-25T15:00:12.916-0300] {standard_task_runner.py:64} INFO - Started process 2619644 to run task
[2024-07-25T15:00:12.918-0300] {standard_task_runner.py:90} INFO - Running: ['airflow', 'tasks', 'run', 'Mercado_5m', 'get_5m_info', 'scheduled__2024-07-25T12:40:00+00:00', '--job-id', '2464', '--raw', '--subdir', 'DAGS_FOLDER/mercado_dag.py', '--cfg-path', '/tmp/tmphebme9yw']
[2024-07-25T15:00:12.920-0300] {standard_task_runner.py:91} INFO - Job 2464: Subtask get_5m_info
[2024-07-25T15:00:12.946-0300] {task_command.py:426} INFO - Running <TaskInstance: Mercado_5m.get_5m_info scheduled__2024-07-25T12:40:00+00:00 [running]> on host Galaxybook.
[2024-07-25T15:00:13.003-0300] {taskinstance.py:2648} INFO - Exporting env vars: AIRFLOW_CTX_DAG_OWNER='airflow' AIRFLOW_CTX_DAG_ID='Mercado_5m' AIRFLOW_CTX_TASK_ID='get_5m_info' AIRFLOW_CTX_EXECUTION_DATE='2024-07-25T12:40:00+00:00' AIRFLOW_CTX_TRY_NUMBER='1' AIRFLOW_CTX_DAG_RUN_ID='scheduled__2024-07-25T12:40:00+00:00'
[2024-07-25T15:00:13.003-0300] {taskinstance.py:430} INFO - ::endgroup::
[2024-07-25T15:00:13.068-0300] {base.py:84} INFO - Using connection ID 'mercado_default' for task execution.
[2024-07-25T15:00:13.069-0300] {mercado_hook.py:31} INFO - URL: https://api.mercadobitcoin.net/api/v4/candles?symbol=BTC-BRL&resolution=5m&to=1721922300&from=1721922000
[2024-07-25T15:00:13.348-0300] {python.py:237} INFO - Done. Returned value was: None
[2024-07-25T15:00:13.348-0300] {taskinstance.py:441} INFO - ::group::Post task execution logs
[2024-07-25T15:00:13.351-0300] {taskinstance.py:1206} INFO - Marking task as SUCCESS. dag_id=Mercado_5m, task_id=get_5m_info, run_id=scheduled__2024-07-25T12:40:00+00:00, execution_date=20240725T124000, start_date=20240725T180012, end_date=20240725T180013
[2024-07-25T15:00:13.379-0300] {local_task_job_runner.py:243} INFO - Task exited with return code 0
[2024-07-25T15:00:13.386-0300] {taskinstance.py:3503} INFO - 0 downstream tasks scheduled from follow-on schedule check
[2024-07-25T15:00:13.386-0300] {local_task_job_runner.py:222} INFO - ::endgroup::
