[2024-07-25T12:57:44.734-0300] {local_task_job_runner.py:120} INFO - ::group::Pre task execution logs
[2024-07-25T12:57:44.739-0300] {taskinstance.py:2076} INFO - Dependencies all met for dep_context=non-requeueable deps ti=<TaskInstance: Binance_5m.get_5m_info manual__2024-07-25T15:57:42.524680+00:00 [queued]>
[2024-07-25T12:57:44.743-0300] {taskinstance.py:2076} INFO - Dependencies all met for dep_context=requeueable deps ti=<TaskInstance: Binance_5m.get_5m_info manual__2024-07-25T15:57:42.524680+00:00 [queued]>
[2024-07-25T12:57:44.743-0300] {taskinstance.py:2306} INFO - Starting attempt 1 of 1
[2024-07-25T12:57:44.758-0300] {taskinstance.py:2330} INFO - Executing <Task(PythonOperator): get_5m_info> on 2024-07-25 15:57:42.524680+00:00
[2024-07-25T12:57:44.760-0300] {standard_task_runner.py:64} INFO - Started process 2546878 to run task
[2024-07-25T12:57:44.763-0300] {standard_task_runner.py:90} INFO - Running: ['airflow', 'tasks', 'run', 'Binance_5m', 'get_5m_info', 'manual__2024-07-25T15:57:42.524680+00:00', '--job-id', '2075', '--raw', '--subdir', 'DAGS_FOLDER/binance_dag.py', '--cfg-path', '/tmp/tmpie9e1kuv']
[2024-07-25T12:57:44.764-0300] {standard_task_runner.py:91} INFO - Job 2075: Subtask get_5m_info
[2024-07-25T12:57:44.789-0300] {task_command.py:426} INFO - Running <TaskInstance: Binance_5m.get_5m_info manual__2024-07-25T15:57:42.524680+00:00 [running]> on host Galaxybook.
[2024-07-25T12:57:44.834-0300] {taskinstance.py:2648} INFO - Exporting env vars: AIRFLOW_CTX_DAG_OWNER='airflow' AIRFLOW_CTX_DAG_ID='Binance_5m' AIRFLOW_CTX_TASK_ID='get_5m_info' AIRFLOW_CTX_EXECUTION_DATE='2024-07-25T15:57:42.524680+00:00' AIRFLOW_CTX_TRY_NUMBER='1' AIRFLOW_CTX_DAG_RUN_ID='manual__2024-07-25T15:57:42.524680+00:00'
[2024-07-25T12:57:44.834-0300] {taskinstance.py:430} INFO - ::endgroup::
[2024-07-25T12:57:44.842-0300] {taskinstance.py:441} INFO - ::group::Post task execution logs
[2024-07-25T12:57:44.842-0300] {taskinstance.py:2905} ERROR - Task failed with exception
Traceback (most recent call last):
  File "/home/hugoviana/Documentos/data_pipeline_airflow/.venv/lib/python3.12/site-packages/airflow/models/taskinstance.py", line 465, in _execute_task
    result = _execute_callable(context=context, **execute_callable_kwargs)
             ^^^^^^^^^^^^^^^^^^^^^^^^^^^^^^^^^^^^^^^^^^^^^^^^^^^^^^^^^^^^^
  File "/home/hugoviana/Documentos/data_pipeline_airflow/.venv/lib/python3.12/site-packages/airflow/models/taskinstance.py", line 432, in _execute_callable
    return execute_callable(context=context, **execute_callable_kwargs)
           ^^^^^^^^^^^^^^^^^^^^^^^^^^^^^^^^^^^^^^^^^^^^^^^^^^^^^^^^^^^^
  File "/home/hugoviana/Documentos/data_pipeline_airflow/.venv/lib/python3.12/site-packages/airflow/models/baseoperator.py", line 401, in wrapper
    return func(self, *args, **kwargs)
           ^^^^^^^^^^^^^^^^^^^^^^^^^^^
  File "/home/hugoviana/Documentos/data_pipeline_airflow/.venv/lib/python3.12/site-packages/airflow/operators/python.py", line 233, in execute
    self.op_kwargs = self.determine_kwargs(context)
                     ^^^^^^^^^^^^^^^^^^^^^^^^^^^^^^
  File "/home/hugoviana/Documentos/data_pipeline_airflow/.venv/lib/python3.12/site-packages/airflow/operators/python.py", line 244, in determine_kwargs
    return KeywordParameters.determine(self.python_callable, self.op_args, context).unpacking()
           ^^^^^^^^^^^^^^^^^^^^^^^^^^^^^^^^^^^^^^^^^^^^^^^^^^^^^^^^^^^^^^^^^^^^^^^^
  File "/home/hugoviana/Documentos/data_pipeline_airflow/.venv/lib/python3.12/site-packages/airflow/utils/operator_helpers.py", line 163, in determine
    raise ValueError(f"The key {name!r} in args is a part of kwargs and therefore reserved.")
ValueError: The key 'data_interval_end' in args is a part of kwargs and therefore reserved.
[2024-07-25T12:57:44.909-0300] {taskinstance.py:1206} INFO - Marking task as FAILED. dag_id=Binance_5m, task_id=get_5m_info, run_id=manual__2024-07-25T15:57:42.524680+00:00, execution_date=20240725T155742, start_date=20240725T155744, end_date=20240725T155744
[2024-07-25T12:57:44.926-0300] {standard_task_runner.py:110} ERROR - Failed to execute job 2075 for task get_5m_info (The key 'data_interval_end' in args is a part of kwargs and therefore reserved.; 2546878)
[2024-07-25T12:57:44.936-0300] {local_task_job_runner.py:243} INFO - Task exited with return code 1
[2024-07-25T12:57:44.942-0300] {taskinstance.py:3503} INFO - 0 downstream tasks scheduled from follow-on schedule check
[2024-07-25T12:57:44.942-0300] {local_task_job_runner.py:222} INFO - ::endgroup::
