[2024-07-25T14:28:32.934-0300] {local_task_job_runner.py:120} INFO - ::group::Pre task execution logs
[2024-07-25T14:28:32.939-0300] {taskinstance.py:2076} INFO - Dependencies all met for dep_context=non-requeueable deps ti=<TaskInstance: Mercado_5m.get_5m_info scheduled__2024-07-25T13:50:00+00:00 [queued]>
[2024-07-25T14:28:32.942-0300] {taskinstance.py:2076} INFO - Dependencies all met for dep_context=requeueable deps ti=<TaskInstance: Mercado_5m.get_5m_info scheduled__2024-07-25T13:50:00+00:00 [queued]>
[2024-07-25T14:28:32.942-0300] {taskinstance.py:2306} INFO - Starting attempt 1 of 1
[2024-07-25T14:28:32.954-0300] {taskinstance.py:2330} INFO - Executing <Task(PythonOperator): get_5m_info> on 2024-07-25 13:50:00+00:00
[2024-07-25T14:28:32.955-0300] {standard_task_runner.py:64} INFO - Started process 2591331 to run task
[2024-07-25T14:28:32.958-0300] {standard_task_runner.py:90} INFO - Running: ['airflow', 'tasks', 'run', 'Mercado_5m', 'get_5m_info', 'scheduled__2024-07-25T13:50:00+00:00', '--job-id', '2126', '--raw', '--subdir', 'DAGS_FOLDER/mercado_dag.py', '--cfg-path', '/tmp/tmpo39zhnjs']
[2024-07-25T14:28:32.959-0300] {standard_task_runner.py:91} INFO - Job 2126: Subtask get_5m_info
[2024-07-25T14:28:32.988-0300] {task_command.py:426} INFO - Running <TaskInstance: Mercado_5m.get_5m_info scheduled__2024-07-25T13:50:00+00:00 [running]> on host Galaxybook.
[2024-07-25T14:28:33.033-0300] {taskinstance.py:2648} INFO - Exporting env vars: AIRFLOW_CTX_DAG_OWNER='airflow' AIRFLOW_CTX_DAG_ID='Mercado_5m' AIRFLOW_CTX_TASK_ID='get_5m_info' AIRFLOW_CTX_EXECUTION_DATE='2024-07-25T13:50:00+00:00' AIRFLOW_CTX_TRY_NUMBER='1' AIRFLOW_CTX_DAG_RUN_ID='scheduled__2024-07-25T13:50:00+00:00'
[2024-07-25T14:28:33.033-0300] {taskinstance.py:430} INFO - ::endgroup::
[2024-07-25T14:28:33.040-0300] {taskinstance.py:441} INFO - ::group::Post task execution logs
[2024-07-25T14:28:33.040-0300] {taskinstance.py:2905} ERROR - Task failed with exception
Traceback (most recent call last):
  File "/home/hugoviana/Documentos/data_pipeline_airflow/.venv/lib/python3.12/site-packages/airflow/models/taskinstance.py", line 465, in _execute_task
    result = _execute_callable(context=context, **execute_callable_kwargs)
             ^^^^^^^^^^^^^^^^^^^^^^^^^^^^^^^^^^^^^^^^^^^^^^^^^^^^^^^^^^^^^
  File "/home/hugoviana/Documentos/data_pipeline_airflow/.venv/lib/python3.12/site-packages/airflow/models/taskinstance.py", line 432, in _execute_callable
    return execute_callable(context=context, **execute_callable_kwargs)
           ^^^^^^^^^^^^^^^^^^^^^^^^^^^^^^^^^^^^^^^^^^^^^^^^^^^^^^^^^^^^
  File "/home/hugoviana/Documentos/data_pipeline_airflow/.venv/lib/python3.12/site-packages/airflow/models/baseoperator.py", line 401, in wrapper
    return func(self, *args, **kwargs)
           ^^^^^^^^^^^^^^^^^^^^^^^^^^^
  File "/home/hugoviana/Documentos/data_pipeline_airflow/.venv/lib/python3.12/site-packages/airflow/operators/python.py", line 232, in execute
    context_merge(context, self.op_kwargs, templates_dict=self.templates_dict)
  File "/home/hugoviana/Documentos/data_pipeline_airflow/.venv/lib/python3.12/site-packages/airflow/utils/context.py", line 266, in context_merge
    context.update(*args, **kwargs)
  File "<frozen _collections_abc>", line 987, in update
ValueError: too many values to unpack (expected 2)
[2024-07-25T14:28:33.044-0300] {taskinstance.py:1206} INFO - Marking task as FAILED. dag_id=Mercado_5m, task_id=get_5m_info, run_id=scheduled__2024-07-25T13:50:00+00:00, execution_date=20240725T135000, start_date=20240725T172832, end_date=20240725T172833
[2024-07-25T14:28:33.057-0300] {standard_task_runner.py:110} ERROR - Failed to execute job 2126 for task get_5m_info (too many values to unpack (expected 2); 2591331)
[2024-07-25T14:28:33.090-0300] {local_task_job_runner.py:243} INFO - Task exited with return code 1
[2024-07-25T14:28:33.099-0300] {taskinstance.py:3503} INFO - 0 downstream tasks scheduled from follow-on schedule check
[2024-07-25T14:28:33.099-0300] {local_task_job_runner.py:222} INFO - ::endgroup::
[2024-07-25T14:30:34.810-0300] {local_task_job_runner.py:120} INFO - ::group::Pre task execution logs
[2024-07-25T14:30:34.815-0300] {taskinstance.py:2076} INFO - Dependencies all met for dep_context=non-requeueable deps ti=<TaskInstance: Mercado_5m.get_5m_info scheduled__2024-07-25T13:50:00+00:00 [queued]>
[2024-07-25T14:30:34.819-0300] {taskinstance.py:2076} INFO - Dependencies all met for dep_context=requeueable deps ti=<TaskInstance: Mercado_5m.get_5m_info scheduled__2024-07-25T13:50:00+00:00 [queued]>
[2024-07-25T14:30:34.819-0300] {taskinstance.py:2306} INFO - Starting attempt 1 of 1
[2024-07-25T14:30:34.835-0300] {taskinstance.py:2330} INFO - Executing <Task(PythonOperator): get_5m_info> on 2024-07-25 13:50:00+00:00
[2024-07-25T14:30:34.836-0300] {standard_task_runner.py:64} INFO - Started process 2593418 to run task
[2024-07-25T14:30:34.838-0300] {standard_task_runner.py:90} INFO - Running: ['airflow', 'tasks', 'run', 'Mercado_5m', 'get_5m_info', 'scheduled__2024-07-25T13:50:00+00:00', '--job-id', '2104', '--raw', '--subdir', 'DAGS_FOLDER/mercado_dag.py', '--cfg-path', '/tmp/tmpyx6jg742']
[2024-07-25T14:30:34.839-0300] {standard_task_runner.py:91} INFO - Job 2104: Subtask get_5m_info
[2024-07-25T14:30:34.865-0300] {task_command.py:426} INFO - Running <TaskInstance: Mercado_5m.get_5m_info scheduled__2024-07-25T13:50:00+00:00 [running]> on host Galaxybook.
[2024-07-25T14:30:34.913-0300] {taskinstance.py:2648} INFO - Exporting env vars: AIRFLOW_CTX_DAG_OWNER='airflow' AIRFLOW_CTX_DAG_ID='Mercado_5m' AIRFLOW_CTX_TASK_ID='get_5m_info' AIRFLOW_CTX_EXECUTION_DATE='2024-07-25T13:50:00+00:00' AIRFLOW_CTX_TRY_NUMBER='1' AIRFLOW_CTX_DAG_RUN_ID='scheduled__2024-07-25T13:50:00+00:00'
[2024-07-25T14:30:34.913-0300] {taskinstance.py:430} INFO - ::endgroup::
[2024-07-25T14:30:34.920-0300] {taskinstance.py:441} INFO - ::group::Post task execution logs
[2024-07-25T14:30:34.921-0300] {taskinstance.py:2905} ERROR - Task failed with exception
Traceback (most recent call last):
  File "/home/hugoviana/Documentos/data_pipeline_airflow/.venv/lib/python3.12/site-packages/airflow/models/taskinstance.py", line 465, in _execute_task
    result = _execute_callable(context=context, **execute_callable_kwargs)
             ^^^^^^^^^^^^^^^^^^^^^^^^^^^^^^^^^^^^^^^^^^^^^^^^^^^^^^^^^^^^^
  File "/home/hugoviana/Documentos/data_pipeline_airflow/.venv/lib/python3.12/site-packages/airflow/models/taskinstance.py", line 432, in _execute_callable
    return execute_callable(context=context, **execute_callable_kwargs)
           ^^^^^^^^^^^^^^^^^^^^^^^^^^^^^^^^^^^^^^^^^^^^^^^^^^^^^^^^^^^^
  File "/home/hugoviana/Documentos/data_pipeline_airflow/.venv/lib/python3.12/site-packages/airflow/models/baseoperator.py", line 401, in wrapper
    return func(self, *args, **kwargs)
           ^^^^^^^^^^^^^^^^^^^^^^^^^^^
  File "/home/hugoviana/Documentos/data_pipeline_airflow/.venv/lib/python3.12/site-packages/airflow/operators/python.py", line 232, in execute
    context_merge(context, self.op_kwargs, templates_dict=self.templates_dict)
  File "/home/hugoviana/Documentos/data_pipeline_airflow/.venv/lib/python3.12/site-packages/airflow/utils/context.py", line 266, in context_merge
    context.update(*args, **kwargs)
  File "<frozen _collections_abc>", line 987, in update
ValueError: too many values to unpack (expected 2)
[2024-07-25T14:30:34.925-0300] {taskinstance.py:1206} INFO - Marking task as FAILED. dag_id=Mercado_5m, task_id=get_5m_info, run_id=scheduled__2024-07-25T13:50:00+00:00, execution_date=20240725T135000, start_date=20240725T173034, end_date=20240725T173034
[2024-07-25T14:30:34.936-0300] {standard_task_runner.py:110} ERROR - Failed to execute job 2104 for task get_5m_info (too many values to unpack (expected 2); 2593418)
[2024-07-25T14:30:34.972-0300] {local_task_job_runner.py:243} INFO - Task exited with return code 1
[2024-07-25T14:30:34.979-0300] {taskinstance.py:3503} INFO - 0 downstream tasks scheduled from follow-on schedule check
[2024-07-25T14:30:34.979-0300] {local_task_job_runner.py:222} INFO - ::endgroup::
[2024-07-25T15:00:45.163-0300] {local_task_job_runner.py:120} INFO - ::group::Pre task execution logs
[2024-07-25T15:00:45.170-0300] {taskinstance.py:2076} INFO - Dependencies all met for dep_context=non-requeueable deps ti=<TaskInstance: Mercado_5m.get_5m_info scheduled__2024-07-25T13:50:00+00:00 [queued]>
[2024-07-25T15:00:45.173-0300] {taskinstance.py:2076} INFO - Dependencies all met for dep_context=requeueable deps ti=<TaskInstance: Mercado_5m.get_5m_info scheduled__2024-07-25T13:50:00+00:00 [queued]>
[2024-07-25T15:00:45.173-0300] {taskinstance.py:2306} INFO - Starting attempt 1 of 1
[2024-07-25T15:00:45.190-0300] {taskinstance.py:2330} INFO - Executing <Task(PythonOperator): get_5m_info> on 2024-07-25 13:50:00+00:00
[2024-07-25T15:00:45.192-0300] {standard_task_runner.py:64} INFO - Started process 2620171 to run task
[2024-07-25T15:00:45.195-0300] {standard_task_runner.py:90} INFO - Running: ['airflow', 'tasks', 'run', 'Mercado_5m', 'get_5m_info', 'scheduled__2024-07-25T13:50:00+00:00', '--job-id', '2478', '--raw', '--subdir', 'DAGS_FOLDER/mercado_dag.py', '--cfg-path', '/tmp/tmppbe9u0wa']
[2024-07-25T15:00:45.196-0300] {standard_task_runner.py:91} INFO - Job 2478: Subtask get_5m_info
[2024-07-25T15:00:45.226-0300] {task_command.py:426} INFO - Running <TaskInstance: Mercado_5m.get_5m_info scheduled__2024-07-25T13:50:00+00:00 [running]> on host Galaxybook.
[2024-07-25T15:00:45.286-0300] {taskinstance.py:2648} INFO - Exporting env vars: AIRFLOW_CTX_DAG_OWNER='airflow' AIRFLOW_CTX_DAG_ID='Mercado_5m' AIRFLOW_CTX_TASK_ID='get_5m_info' AIRFLOW_CTX_EXECUTION_DATE='2024-07-25T13:50:00+00:00' AIRFLOW_CTX_TRY_NUMBER='1' AIRFLOW_CTX_DAG_RUN_ID='scheduled__2024-07-25T13:50:00+00:00'
[2024-07-25T15:00:45.287-0300] {taskinstance.py:430} INFO - ::endgroup::
[2024-07-25T15:00:45.355-0300] {base.py:84} INFO - Using connection ID 'mercado_default' for task execution.
[2024-07-25T15:00:45.356-0300] {mercado_hook.py:31} INFO - URL: https://api.mercadobitcoin.net/api/v4/candles?symbol=BTC-BRL&resolution=5m&to=1721926500&from=1721926200
[2024-07-25T15:00:50.654-0300] {python.py:237} INFO - Done. Returned value was: None
[2024-07-25T15:00:50.655-0300] {taskinstance.py:441} INFO - ::group::Post task execution logs
[2024-07-25T15:00:50.658-0300] {taskinstance.py:1206} INFO - Marking task as SUCCESS. dag_id=Mercado_5m, task_id=get_5m_info, run_id=scheduled__2024-07-25T13:50:00+00:00, execution_date=20240725T135000, start_date=20240725T180045, end_date=20240725T180050
[2024-07-25T15:00:50.706-0300] {local_task_job_runner.py:243} INFO - Task exited with return code 0
[2024-07-25T15:00:50.711-0300] {taskinstance.py:3503} INFO - 0 downstream tasks scheduled from follow-on schedule check
[2024-07-25T15:00:50.712-0300] {local_task_job_runner.py:222} INFO - ::endgroup::
