[2024-07-25T14:28:02.645-0300] {local_task_job_runner.py:120} INFO - ::group::Pre task execution logs
[2024-07-25T14:28:02.651-0300] {taskinstance.py:2076} INFO - Dependencies all met for dep_context=non-requeueable deps ti=<TaskInstance: Mercado_5m.get_5m_info scheduled__2024-07-25T13:00:00+00:00 [queued]>
[2024-07-25T14:28:02.655-0300] {taskinstance.py:2076} INFO - Dependencies all met for dep_context=requeueable deps ti=<TaskInstance: Mercado_5m.get_5m_info scheduled__2024-07-25T13:00:00+00:00 [queued]>
[2024-07-25T14:28:02.655-0300] {taskinstance.py:2306} INFO - Starting attempt 1 of 1
[2024-07-25T14:28:02.669-0300] {taskinstance.py:2330} INFO - Executing <Task(PythonOperator): get_5m_info> on 2024-07-25 13:00:00+00:00
[2024-07-25T14:28:02.671-0300] {standard_task_runner.py:64} INFO - Started process 2590799 to run task
[2024-07-25T14:28:02.673-0300] {standard_task_runner.py:90} INFO - Running: ['airflow', 'tasks', 'run', 'Mercado_5m', 'get_5m_info', 'scheduled__2024-07-25T13:00:00+00:00', '--job-id', '2106', '--raw', '--subdir', 'DAGS_FOLDER/mercado_dag.py', '--cfg-path', '/tmp/tmput0tsawj']
[2024-07-25T14:28:02.673-0300] {standard_task_runner.py:91} INFO - Job 2106: Subtask get_5m_info
[2024-07-25T14:28:02.717-0300] {task_command.py:426} INFO - Running <TaskInstance: Mercado_5m.get_5m_info scheduled__2024-07-25T13:00:00+00:00 [running]> on host Galaxybook.
[2024-07-25T14:28:02.773-0300] {taskinstance.py:2648} INFO - Exporting env vars: AIRFLOW_CTX_DAG_OWNER='airflow' AIRFLOW_CTX_DAG_ID='Mercado_5m' AIRFLOW_CTX_TASK_ID='get_5m_info' AIRFLOW_CTX_EXECUTION_DATE='2024-07-25T13:00:00+00:00' AIRFLOW_CTX_TRY_NUMBER='1' AIRFLOW_CTX_DAG_RUN_ID='scheduled__2024-07-25T13:00:00+00:00'
[2024-07-25T14:28:02.773-0300] {taskinstance.py:430} INFO - ::endgroup::
[2024-07-25T14:28:02.786-0300] {taskinstance.py:441} INFO - ::group::Post task execution logs
[2024-07-25T14:28:02.787-0300] {taskinstance.py:2905} ERROR - Task failed with exception
Traceback (most recent call last):
  File "/home/hugoviana/Documentos/data_pipeline_airflow/.venv/lib/python3.12/site-packages/airflow/models/taskinstance.py", line 465, in _execute_task
    result = _execute_callable(context=context, **execute_callable_kwargs)
             ^^^^^^^^^^^^^^^^^^^^^^^^^^^^^^^^^^^^^^^^^^^^^^^^^^^^^^^^^^^^^
  File "/home/hugoviana/Documentos/data_pipeline_airflow/.venv/lib/python3.12/site-packages/airflow/models/taskinstance.py", line 432, in _execute_callable
    return execute_callable(context=context, **execute_callable_kwargs)
           ^^^^^^^^^^^^^^^^^^^^^^^^^^^^^^^^^^^^^^^^^^^^^^^^^^^^^^^^^^^^
  File "/home/hugoviana/Documentos/data_pipeline_airflow/.venv/lib/python3.12/site-packages/airflow/models/baseoperator.py", line 401, in wrapper
    return func(self, *args, **kwargs)
           ^^^^^^^^^^^^^^^^^^^^^^^^^^^
  File "/home/hugoviana/Documentos/data_pipeline_airflow/.venv/lib/python3.12/site-packages/airflow/operators/python.py", line 232, in execute
    context_merge(context, self.op_kwargs, templates_dict=self.templates_dict)
  File "/home/hugoviana/Documentos/data_pipeline_airflow/.venv/lib/python3.12/site-packages/airflow/utils/context.py", line 266, in context_merge
    context.update(*args, **kwargs)
  File "<frozen _collections_abc>", line 987, in update
ValueError: too many values to unpack (expected 2)
[2024-07-25T14:28:02.792-0300] {taskinstance.py:1206} INFO - Marking task as FAILED. dag_id=Mercado_5m, task_id=get_5m_info, run_id=scheduled__2024-07-25T13:00:00+00:00, execution_date=20240725T130000, start_date=20240725T172802, end_date=20240725T172802
[2024-07-25T14:28:02.810-0300] {standard_task_runner.py:110} ERROR - Failed to execute job 2106 for task get_5m_info (too many values to unpack (expected 2); 2590799)
[2024-07-25T14:28:02.848-0300] {local_task_job_runner.py:243} INFO - Task exited with return code 1
[2024-07-25T14:28:02.855-0300] {taskinstance.py:3503} INFO - 0 downstream tasks scheduled from follow-on schedule check
[2024-07-25T14:28:02.856-0300] {local_task_job_runner.py:222} INFO - ::endgroup::
[2024-07-25T14:30:17.013-0300] {local_task_job_runner.py:120} INFO - ::group::Pre task execution logs
[2024-07-25T14:30:17.019-0300] {taskinstance.py:2076} INFO - Dependencies all met for dep_context=non-requeueable deps ti=<TaskInstance: Mercado_5m.get_5m_info scheduled__2024-07-25T13:00:00+00:00 [queued]>
[2024-07-25T14:30:17.022-0300] {taskinstance.py:2076} INFO - Dependencies all met for dep_context=requeueable deps ti=<TaskInstance: Mercado_5m.get_5m_info scheduled__2024-07-25T13:00:00+00:00 [queued]>
[2024-07-25T14:30:17.022-0300] {taskinstance.py:2306} INFO - Starting attempt 1 of 1
[2024-07-25T14:30:17.034-0300] {taskinstance.py:2330} INFO - Executing <Task(PythonOperator): get_5m_info> on 2024-07-25 13:00:00+00:00
[2024-07-25T14:30:17.036-0300] {standard_task_runner.py:64} INFO - Started process 2593135 to run task
[2024-07-25T14:30:17.038-0300] {standard_task_runner.py:90} INFO - Running: ['airflow', 'tasks', 'run', 'Mercado_5m', 'get_5m_info', 'scheduled__2024-07-25T13:00:00+00:00', '--job-id', '2094', '--raw', '--subdir', 'DAGS_FOLDER/mercado_dag.py', '--cfg-path', '/tmp/tmp9aaaisib']
[2024-07-25T14:30:17.039-0300] {standard_task_runner.py:91} INFO - Job 2094: Subtask get_5m_info
[2024-07-25T14:30:17.067-0300] {task_command.py:426} INFO - Running <TaskInstance: Mercado_5m.get_5m_info scheduled__2024-07-25T13:00:00+00:00 [running]> on host Galaxybook.
[2024-07-25T14:30:17.120-0300] {taskinstance.py:2648} INFO - Exporting env vars: AIRFLOW_CTX_DAG_OWNER='airflow' AIRFLOW_CTX_DAG_ID='Mercado_5m' AIRFLOW_CTX_TASK_ID='get_5m_info' AIRFLOW_CTX_EXECUTION_DATE='2024-07-25T13:00:00+00:00' AIRFLOW_CTX_TRY_NUMBER='1' AIRFLOW_CTX_DAG_RUN_ID='scheduled__2024-07-25T13:00:00+00:00'
[2024-07-25T14:30:17.120-0300] {taskinstance.py:430} INFO - ::endgroup::
[2024-07-25T14:30:17.128-0300] {taskinstance.py:441} INFO - ::group::Post task execution logs
[2024-07-25T14:30:17.129-0300] {taskinstance.py:2905} ERROR - Task failed with exception
Traceback (most recent call last):
  File "/home/hugoviana/Documentos/data_pipeline_airflow/.venv/lib/python3.12/site-packages/airflow/models/taskinstance.py", line 465, in _execute_task
    result = _execute_callable(context=context, **execute_callable_kwargs)
             ^^^^^^^^^^^^^^^^^^^^^^^^^^^^^^^^^^^^^^^^^^^^^^^^^^^^^^^^^^^^^
  File "/home/hugoviana/Documentos/data_pipeline_airflow/.venv/lib/python3.12/site-packages/airflow/models/taskinstance.py", line 432, in _execute_callable
    return execute_callable(context=context, **execute_callable_kwargs)
           ^^^^^^^^^^^^^^^^^^^^^^^^^^^^^^^^^^^^^^^^^^^^^^^^^^^^^^^^^^^^
  File "/home/hugoviana/Documentos/data_pipeline_airflow/.venv/lib/python3.12/site-packages/airflow/models/baseoperator.py", line 401, in wrapper
    return func(self, *args, **kwargs)
           ^^^^^^^^^^^^^^^^^^^^^^^^^^^
  File "/home/hugoviana/Documentos/data_pipeline_airflow/.venv/lib/python3.12/site-packages/airflow/operators/python.py", line 232, in execute
    context_merge(context, self.op_kwargs, templates_dict=self.templates_dict)
  File "/home/hugoviana/Documentos/data_pipeline_airflow/.venv/lib/python3.12/site-packages/airflow/utils/context.py", line 266, in context_merge
    context.update(*args, **kwargs)
  File "<frozen _collections_abc>", line 987, in update
ValueError: too many values to unpack (expected 2)
[2024-07-25T14:30:17.133-0300] {taskinstance.py:1206} INFO - Marking task as FAILED. dag_id=Mercado_5m, task_id=get_5m_info, run_id=scheduled__2024-07-25T13:00:00+00:00, execution_date=20240725T130000, start_date=20240725T173017, end_date=20240725T173017
[2024-07-25T14:30:17.213-0300] {standard_task_runner.py:110} ERROR - Failed to execute job 2094 for task get_5m_info (too many values to unpack (expected 2); 2593135)
[2024-07-25T14:30:17.253-0300] {local_task_job_runner.py:243} INFO - Task exited with return code 1
[2024-07-25T14:30:17.259-0300] {taskinstance.py:3503} INFO - 0 downstream tasks scheduled from follow-on schedule check
[2024-07-25T14:30:17.260-0300] {local_task_job_runner.py:222} INFO - ::endgroup::
[2024-07-25T15:00:20.790-0300] {local_task_job_runner.py:120} INFO - ::group::Pre task execution logs
[2024-07-25T15:00:20.795-0300] {taskinstance.py:2076} INFO - Dependencies all met for dep_context=non-requeueable deps ti=<TaskInstance: Mercado_5m.get_5m_info scheduled__2024-07-25T13:00:00+00:00 [queued]>
[2024-07-25T15:00:20.799-0300] {taskinstance.py:2076} INFO - Dependencies all met for dep_context=requeueable deps ti=<TaskInstance: Mercado_5m.get_5m_info scheduled__2024-07-25T13:00:00+00:00 [queued]>
[2024-07-25T15:00:20.799-0300] {taskinstance.py:2306} INFO - Starting attempt 1 of 1
[2024-07-25T15:00:20.813-0300] {taskinstance.py:2330} INFO - Executing <Task(PythonOperator): get_5m_info> on 2024-07-25 13:00:00+00:00
[2024-07-25T15:00:20.815-0300] {standard_task_runner.py:64} INFO - Started process 2619768 to run task
[2024-07-25T15:00:20.817-0300] {standard_task_runner.py:90} INFO - Running: ['airflow', 'tasks', 'run', 'Mercado_5m', 'get_5m_info', 'scheduled__2024-07-25T13:00:00+00:00', '--job-id', '2468', '--raw', '--subdir', 'DAGS_FOLDER/mercado_dag.py', '--cfg-path', '/tmp/tmpst6zat5l']
[2024-07-25T15:00:20.818-0300] {standard_task_runner.py:91} INFO - Job 2468: Subtask get_5m_info
[2024-07-25T15:00:20.842-0300] {task_command.py:426} INFO - Running <TaskInstance: Mercado_5m.get_5m_info scheduled__2024-07-25T13:00:00+00:00 [running]> on host Galaxybook.
[2024-07-25T15:00:20.893-0300] {taskinstance.py:2648} INFO - Exporting env vars: AIRFLOW_CTX_DAG_OWNER='airflow' AIRFLOW_CTX_DAG_ID='Mercado_5m' AIRFLOW_CTX_TASK_ID='get_5m_info' AIRFLOW_CTX_EXECUTION_DATE='2024-07-25T13:00:00+00:00' AIRFLOW_CTX_TRY_NUMBER='1' AIRFLOW_CTX_DAG_RUN_ID='scheduled__2024-07-25T13:00:00+00:00'
[2024-07-25T15:00:20.894-0300] {taskinstance.py:430} INFO - ::endgroup::
[2024-07-25T15:00:20.955-0300] {base.py:84} INFO - Using connection ID 'mercado_default' for task execution.
[2024-07-25T15:00:20.956-0300] {mercado_hook.py:31} INFO - URL: https://api.mercadobitcoin.net/api/v4/candles?symbol=BTC-BRL&resolution=5m&to=1721923500&from=1721923200
[2024-07-25T15:00:21.246-0300] {python.py:237} INFO - Done. Returned value was: None
[2024-07-25T15:00:21.246-0300] {taskinstance.py:441} INFO - ::group::Post task execution logs
[2024-07-25T15:00:21.249-0300] {taskinstance.py:1206} INFO - Marking task as SUCCESS. dag_id=Mercado_5m, task_id=get_5m_info, run_id=scheduled__2024-07-25T13:00:00+00:00, execution_date=20240725T130000, start_date=20240725T180020, end_date=20240725T180021
[2024-07-25T15:00:21.279-0300] {local_task_job_runner.py:243} INFO - Task exited with return code 0
[2024-07-25T15:00:21.287-0300] {taskinstance.py:3503} INFO - 0 downstream tasks scheduled from follow-on schedule check
[2024-07-25T15:00:21.287-0300] {local_task_job_runner.py:222} INFO - ::endgroup::
