[2024-07-25T00:00:07.261-0300] {local_task_job_runner.py:120} INFO - ::group::Pre task execution logs
[2024-07-25T00:00:07.267-0300] {taskinstance.py:2076} INFO - Dependencies all met for dep_context=non-requeueable deps ti=<TaskInstance: Mercado_1m.get_1m_info scheduled__2024-07-25T02:59:00+00:00 [queued]>
[2024-07-25T00:00:07.270-0300] {taskinstance.py:2076} INFO - Dependencies all met for dep_context=requeueable deps ti=<TaskInstance: Mercado_1m.get_1m_info scheduled__2024-07-25T02:59:00+00:00 [queued]>
[2024-07-25T00:00:07.270-0300] {taskinstance.py:2306} INFO - Starting attempt 1 of 1
[2024-07-25T00:00:07.285-0300] {taskinstance.py:2330} INFO - Executing <Task(PythonOperator): get_1m_info> on 2024-07-25 02:59:00+00:00
[2024-07-25T00:00:07.287-0300] {standard_task_runner.py:64} INFO - Started process 2289189 to run task
[2024-07-25T00:00:07.289-0300] {standard_task_runner.py:90} INFO - Running: ['airflow', 'tasks', 'run', 'Mercado_1m', 'get_1m_info', 'scheduled__2024-07-25T02:59:00+00:00', '--job-id', '1794', '--raw', '--subdir', 'DAGS_FOLDER/mercado_dag.py', '--cfg-path', '/tmp/tmpd8idgppa']
[2024-07-25T00:00:07.290-0300] {standard_task_runner.py:91} INFO - Job 1794: Subtask get_1m_info
[2024-07-25T00:00:07.315-0300] {task_command.py:426} INFO - Running <TaskInstance: Mercado_1m.get_1m_info scheduled__2024-07-25T02:59:00+00:00 [running]> on host Galaxybook.
[2024-07-25T00:00:07.369-0300] {taskinstance.py:2648} INFO - Exporting env vars: AIRFLOW_CTX_DAG_OWNER='airflow' AIRFLOW_CTX_DAG_ID='Mercado_1m' AIRFLOW_CTX_TASK_ID='get_1m_info' AIRFLOW_CTX_EXECUTION_DATE='2024-07-25T02:59:00+00:00' AIRFLOW_CTX_TRY_NUMBER='1' AIRFLOW_CTX_DAG_RUN_ID='scheduled__2024-07-25T02:59:00+00:00'
[2024-07-25T00:00:07.369-0300] {taskinstance.py:430} INFO - ::endgroup::
[2024-07-25T00:00:07.376-0300] {mercado_hook.py:26} INFO - BASE URL: 
[2024-07-25T00:00:07.379-0300] {base.py:84} INFO - Using connection ID 'mercado_default' for task execution.
[2024-07-25T00:00:07.380-0300] {taskinstance.py:441} INFO - ::group::Post task execution logs
[2024-07-25T00:00:07.380-0300] {taskinstance.py:2905} ERROR - Task failed with exception
Traceback (most recent call last):
  File "/home/hugoviana/Documentos/data_pipeline_airflow/.venv/lib/python3.12/site-packages/airflow/models/taskinstance.py", line 465, in _execute_task
    result = _execute_callable(context=context, **execute_callable_kwargs)
             ^^^^^^^^^^^^^^^^^^^^^^^^^^^^^^^^^^^^^^^^^^^^^^^^^^^^^^^^^^^^^
  File "/home/hugoviana/Documentos/data_pipeline_airflow/.venv/lib/python3.12/site-packages/airflow/models/taskinstance.py", line 432, in _execute_callable
    return execute_callable(context=context, **execute_callable_kwargs)
           ^^^^^^^^^^^^^^^^^^^^^^^^^^^^^^^^^^^^^^^^^^^^^^^^^^^^^^^^^^^^
  File "/home/hugoviana/Documentos/data_pipeline_airflow/.venv/lib/python3.12/site-packages/airflow/models/baseoperator.py", line 401, in wrapper
    return func(self, *args, **kwargs)
           ^^^^^^^^^^^^^^^^^^^^^^^^^^^
  File "/home/hugoviana/Documentos/data_pipeline_airflow/.venv/lib/python3.12/site-packages/airflow/operators/python.py", line 235, in execute
    return_value = self.execute_callable()
                   ^^^^^^^^^^^^^^^^^^^^^^^
  File "/home/hugoviana/Documentos/data_pipeline_airflow/.venv/lib/python3.12/site-packages/airflow/operators/python.py", line 252, in execute_callable
    return self.python_callable(*self.op_args, **self.op_kwargs)
           ^^^^^^^^^^^^^^^^^^^^^^^^^^^^^^^^^^^^^^^^^^^^^^^^^^^^^
  File "/home/hugoviana/Projetos/crypto-etl/airflow_pipeline/dags/mercado_dag.py", line 28, in execute
    ).run()
      ^^^^^
  File "/home/hugoviana/Projetos/crypto-etl/airflow_pipeline/hook/mercado_hook.py", line 38, in run
    return self.connect_to_endpoint(url)
           ^^^^^^^^^^^^^^^^^^^^^^^^^^^^^
  File "/home/hugoviana/Projetos/crypto-etl/airflow_pipeline/hook/mercado_hook.py", line 32, in connect_to_endpoint
    prep = session.prepare_request(request)
           ^^^^^^^^^^^^^^^^^^^^^^^^^^^^^^^^
  File "/home/hugoviana/Documentos/data_pipeline_airflow/.venv/lib/python3.12/site-packages/requests/sessions.py", line 486, in prepare_request
    p.prepare(
  File "/home/hugoviana/Documentos/data_pipeline_airflow/.venv/lib/python3.12/site-packages/requests/models.py", line 368, in prepare
    self.prepare_url(url, params)
  File "/home/hugoviana/Documentos/data_pipeline_airflow/.venv/lib/python3.12/site-packages/requests/models.py", line 439, in prepare_url
    raise MissingSchema(
requests.exceptions.MissingSchema: Invalid URL '/candles?symbol=BTC-BRL&resolution=1m&to=1721876347&from=1721876347': No scheme supplied. Perhaps you meant https:///candles?symbol=BTC-BRL&resolution=1m&to=1721876347&from=1721876347?
[2024-07-25T00:00:07.384-0300] {taskinstance.py:1206} INFO - Marking task as FAILED. dag_id=Mercado_1m, task_id=get_1m_info, run_id=scheduled__2024-07-25T02:59:00+00:00, execution_date=20240725T025900, start_date=20240725T030007, end_date=20240725T030007
[2024-07-25T00:00:07.457-0300] {standard_task_runner.py:110} ERROR - Failed to execute job 1794 for task get_1m_info (Invalid URL '/candles?symbol=BTC-BRL&resolution=1m&to=1721876347&from=1721876347': No scheme supplied. Perhaps you meant https:///candles?symbol=BTC-BRL&resolution=1m&to=1721876347&from=1721876347?; 2289189)
[2024-07-25T00:00:07.464-0300] {local_task_job_runner.py:243} INFO - Task exited with return code 1
[2024-07-25T00:00:07.471-0300] {taskinstance.py:3503} INFO - 0 downstream tasks scheduled from follow-on schedule check
[2024-07-25T00:00:07.471-0300] {local_task_job_runner.py:222} INFO - ::endgroup::
